Workbook

Sheet Retail Sales
A1: Order ID | B1: Order Date | C1: Customer ID | D1: Customer Name | E1: Age | F1: Age Group | G1: Gender | H1: Region | I1: City | J1: Product Category | K1: Product Name | L1: Quantity | M1: Unit Price | N1: Discount_Product | O1: Sales Amount | P1: Profit | Q1: Profit Margin | R1: Shipping Cost | S1: Payment Method | T1: Customer Satisfaction | U1: Return Flag | V1: Order Status | W1: Days to Ship
A2: ORD-00011 | B2: =_xlfn.XLOOKUP(A2,A1:A600,[1]Sheet3!C78:C677) -> 43833 | C2: =_xlfn.XLOOKUP(A2,A1:A600,[1]Sheet3!D78:D677) -> CUST64950 | D2: =_xlfn.XLOOKUP(A2,A1:A600,[1]Sheet3!E78:E677) -> Nisha Mehta | E2: =_xlfn.XLOOKUP(A2,A1:A600,[1]Sheet3!G78:G677) -> 23 | F2: =_xlfn.XLOOKUP('Retail Sales'!A79,'Retail Sales'!A78:A677,[1]Sheet3!H78:H677) -> Young Adult | G2: =_xlfn.XLOOKUP(A2,A1:A600,[1]Sheet3!J78:J677) -> Female | H2: =_xlfn.XLOOKUP(A2,A1:A600,[1]Sheet3!K78:K677) -> South | I2: =_xlfn.XLOOKUP(A2,A1:A600,[1]Sheet3!L78:L677) -> Hyderabad | J2: =_xlfn.XLOOKUP(A2,A1:A600,[1]Sheet3!M78:M677) -> Furniture | K2: =_xlfn.XLOOKUP('Retail Sales'!A79,'Retail Sales'!A78:A677,[1]Sheet3!N78:N677) -> Sofa | L2: =_xlfn.XLOOKUP(A2,A1:A600,[1]Sheet3!P78:P677) -> 8 | M2: =_xlfn.XLOOKUP(A2,A1:A600,[1]Sheet3!Q78:Q677) -> 22523.15 | N2: =_xlfn.XLOOKUP(A2,A1:A600,[1]Sheet3!S78:S677) -> 0.34 | O2: =_xlfn.XLOOKUP(A2,A1:A600,[1]Sheet3!T78:T677) -> 95036.79 | P2: =_xlfn.XLOOKUP(A2,A1:A600,[1]Sheet3!U78:U677) -> 29818.97 | Q2: =_xlfn.XLOOKUP(A2,A1:A600,[1]Sheet3!V78:V677) -> 0.31376239 | R2: =_xlfn.XLOOKUP(A2,A1:A600,[1]Sheet3!W78:W677) -> 65.72 | S2: =_xlfn.XLOOKUP(A2,A1:A600,[1]Sheet3!X78:X677) -> EMI | T2: =_xlfn.XLOOKUP(A2,A1:A600,[1]Sheet3!Z78:Z677) -> 2 | U2: =_xlfn.XLOOKUP(A2,A1:A600,[1]Sheet3!AA78:AA677) -> FALSE | V2: =_xlfn.XLOOKUP(A2,A1:A600,[1]Sheet3!AC78:AC677) -> Delivered | W2: =_xlfn.XLOOKUP(A2,A1:A600,[1]Sheet3!AE78:AE677) -> 5
A3: ORD-00020 | B3: =_xlfn.XLOOKUP(A3,A2:A601,[1]Sheet3!C462:C1061) -> 43838 | C3: =_xlfn.XLOOKUP(A3,A2:A601,[1]Sheet3!D462:D1061) -> CUST05879 | D3: =_xlfn.XLOOKUP(A3,A2:A601,[1]Sheet3!E462:E1061) -> Nisha Nair | E3: =_xlfn.XLOOKUP(A3,A2:A601,[1]Sheet3!G462:G1061) -> 12 | F3: =_xlfn.XLOOKUP('Retail Sales'!A463,'Retail Sales'!A462:A1061,[1]Sheet3!H462:H1061) -> Child | G3: =_xlfn.XLOOKUP(A3,A2:A601,[1]Sheet3!J462:J1061) -> Other | H3: =_xlfn.XLOOKUP(A3,A2:A601,[1]Sheet3!K462:K1061) -> Central | I3: =_xlfn.XLOOKUP(A3,A2:A601,[1]Sheet3!L462:L1061) -> Nagpur | J3: =_xlfn.XLOOKUP(A3,A2:A601,[1]Sheet3!M462:M1061) -> Sports | K3: =_xlfn.XLOOKUP('Retail Sales'!A463,'Retail Sales'!A462:A1061,[1]Sheet3!N462:N1061) -> Dumbbells | L3: =_xlfn.XLOOKUP(A3,A2:A601,[1]Sheet3!P462:P1061) -> 2 | M3: =_xlfn.XLOOKUP(A3,A2:A601,[1]Sheet3!Q462:Q1061) -> 2448.88 | N3: =_xlfn.XLOOKUP(A3,A2:A601,[1]Sheet3!S462:S1061) -> 0.08 | O3: =_xlfn.XLOOKUP(A3,A2:A601,[1]Sheet3!T462:T1061) -> 3192.22 | P3: =_xlfn.XLOOKUP(A3,A2:A601,[1]Sheet3!U462:U1061) -> 355.63 | Q3: =_xlfn.XLOOKUP(A3,A2:A601,[1]Sheet3!V462:V1061) -> 0.11140523 | R3: =_xlfn.XLOOKUP(A3,A2:A601,[1]Sheet3!W462:W1061) -> 47.54 | S3: =_xlfn.XLOOKUP(A3,A2:A601,[1]Sheet3!X462:X1061) -> Cash on Delivery | T3: =_xlfn.XLOOKUP(A3,A2:A601,[1]Sheet3!Z462:Z1061) -> 3 | U3: =_xlfn.XLOOKUP(A3,A2:A601,[1]Sheet3!AA462:AA1061) -> FALSE | V3: =_xlfn.XLOOKUP(A3,A2:A601,[1]Sheet3!AC462:AC1061) -> Delivered | W3: =_xlfn.XLOOKUP(A3,A2:A601,[1]Sheet3!AE462:AE1061) -> 9
A4: ORD-00025 | B4: =_xlfn.XLOOKUP(A4,A3:A602,[1]Sheet3!C40:C639) -> 43840 | C4: =_xlfn.XLOOKUP(A4,A3:A602,[1]Sheet3!D40:D639) -> CUST91373 | D4: =_xlfn.XLOOKUP(A4,A3:A602,[1]Sheet3!E40:E639) -> Karan Iyer | E4: =_xlfn.XLOOKUP(A4,A3:A602,[1]Sheet3!G40:G639) -> 52 | F4: =_xlfn.XLOOKUP('Retail Sales'!A41,'Retail Sales'!A40:A639,[1]Sheet3!H40:H639) -> Senior | G4: =_xlfn.XLOOKUP(A4,A3:A602,[1]Sheet3!J40:J639) -> Female | H4: =_xlfn.XLOOKUP(A4,A3:A602,[1]Sheet3!K40:K639) -> West | I4: =_xlfn.XLOOKUP(A4,A3:A602,[1]Sheet3!L40:L639) -> Mumbai | J4: =_xlfn.XLOOKUP(A4,A3:A602,[1]Sheet3!M40:M639) -> Books | K4: =_xlfn.XLOOKUP('Retail Sales'!A41,'Retail Sales'!A40:A639,[1]Sheet3!N40:N639) -> Cook Book | L4: =_xlfn.XLOOKUP(A4,A3:A602,[1]Sheet3!P40:P639) -> 10 | M4: =_xlfn.XLOOKUP(A4,A3:A602,[1]Sheet3!Q40:Q639) -> 324.41 | N4: =_xlfn.XLOOKUP(A4,A3:A602,[1]Sheet3!S40:S639) -> 0.32 | O4: =_xlfn.XLOOKUP(A4,A3:A602,[1]Sheet3!T40:T639) -> 1810.18 | P4: =_xlfn.XLOOKUP(A4,A3:A602,[1]Sheet3!U40:U639) -> 903.99 | Q4: =_xlfn.XLOOKUP(A4,A3:A602,[1]Sheet3!V40:V639) -> 0.49939233 | R4: =_xlfn.XLOOKUP(A4,A3:A602,[1]Sheet3!W40:W639) -> 48.24 | S4: =_xlfn.XLOOKUP(A4,A3:A602,[1]Sheet3!X40:X639) -> UPI | T4: =_xlfn.XLOOKUP(A4,A3:A602,[1]Sheet3!Z40:Z639) -> 3 | U4: =_xlfn.XLOOKUP(A4,A3:A602,[1]Sheet3!AA40:AA639) -> FALSE | V4: =_xlfn.XLOOKUP(A4,A3:A602,[1]Sheet3!AC40:AC639) -> Delivered | W4: =_xlfn.XLOOKUP(A4,A3:A602,[1]Sheet3!AE40:AE639) -> 4
A5: ORD-00028 | B5: =_xlfn.XLOOKUP(A5,A4:A603,[1]Sheet3!C554:C1153) -> 43841 | C5: =_xlfn.XLOOKUP(A5,A4:A603,[1]Sheet3!D554:D1153) -> CUST03400 | D5: =_xlfn.XLOOKUP(A5,A4:A603,[1]Sheet3!E554:E1153) -> Karan Mishra | E5: =_xlfn.XLOOKUP(A5,A4:A603,[1]Sheet3!G554:G1153) -> 23 | F5: =_xlfn.XLOOKUP('Retail Sales'!A555,'Retail Sales'!A554:A1153,[1]Sheet3!H554:H1153) -> Young Adult | G5: =_xlfn.XLOOKUP(A5,A4:A603,[1]Sheet3!J554:J1153) -> Male | H5: =_xlfn.XLOOKUP(A5,A4:A603,[1]Sheet3!K554:K1153) -> Central | I5: =_xlfn.XLOOKUP(A5,A4:A603,[1]Sheet3!L554:L1153) -> Indore | J5: =_xlfn.XLOOKUP(A5,A4:A603,[1]Sheet3!M554:M1153) -> Sports | K5: =_xlfn.XLOOKUP('Retail Sales'!A555,'Retail Sales'!A554:A1153,[1]Sheet3!N554:N1153) -> Football | L5: =_xlfn.XLOOKUP(A5,A4:A603,[1]Sheet3!P554:P1153) -> 7 | M5: =_xlfn.XLOOKUP(A5,A4:A603,[1]Sheet3!Q554:Q1153) -> 12178.99 | N5: =_xlfn.XLOOKUP(A5,A4:A603,[1]Sheet3!S554:S1153) -> 0.01 | O5: =_xlfn.XLOOKUP(A5,A4:A603,[1]Sheet3!T554:T1153) -> 66009.55 | P5: =_xlfn.XLOOKUP(A5,A4:A603,[1]Sheet3!U554:U1153) -> 17076.44 | Q5: =_xlfn.XLOOKUP(A5,A4:A603,[1]Sheet3!V554:V1153) -> 0.25869651 | R5: =_xlfn.XLOOKUP(A5,A4:A603,[1]Sheet3!W554:W1153) -> 51.51 | S5: =_xlfn.XLOOKUP(A5,A4:A603,[1]Sheet3!X554:X1153) -> UPI | T5: =_xlfn.XLOOKUP(A5,A4:A603,[1]Sheet3!Z554:Z1153) -> 5 | U5: =_xlfn.XLOOKUP(A5,A4:A603,[1]Sheet3!AA554:AA1153) -> FALSE | V5: =_xlfn.XLOOKUP(A5,A4:A603,[1]Sheet3!AC554:AC1153) -> Cancelled | W5: =_xlfn.XLOOKUP(A5,A4:A603,[1]Sheet3!AE554:AE1153) -> 10
A6: ORD-00034 | B6: =_xlfn.XLOOKUP(A6,A5:A604,[1]Sheet3!C294:C893) -> 43842 | C6: =_xlfn.XLOOKUP(A6,A5:A604,[1]Sheet3!D294:D893) -> CUST21613 | D6: =_xlfn.XLOOKUP(A6,A5:A604,[1]Sheet3!E294:E893) -> Arjun Das | E6: =_xlfn.XLOOKUP(A6,A5:A604,[1]Sheet3!G294:G893) -> 49 | F6: =_xlfn.XLOOKUP('Retail Sales'!A295,'Retail Sales'!A294:A893,[1]Sheet3!H294:H893) -> Adult | G6: =_xlfn.XLOOKUP(A6,A5:A604,[1]Sheet3!J294:J893) -> Other | H6: =_xlfn.XLOOKUP(A6,A5:A604,[1]Sheet3!K294:K893) -> West | I6: =_xlfn.XLOOKUP(A6,A5:A604,[1]Sheet3!L294:L893) -> Mumbai | J6: =_xlfn.XLOOKUP(A6,A5:A604,[1]Sheet3!M294:M893) -> Groceries | K6: =_xlfn.XLOOKUP('Retail Sales'!A295,'Retail Sales'!A294:A893,[1]Sheet3!N294:N893) -> Flour | L6: =_xlfn.XLOOKUP(A6,A5:A604,[1]Sheet3!P294:P893) -> 7.0954861 | M6: =_xlfn.XLOOKUP(A6,A5:A604,[1]Sheet3!Q294:Q893) -> 315.85 | N6: =_xlfn.XLOOKUP(A6,A5:A604,[1]Sheet3!S294:S893) -> 0.13 | O6: =_xlfn.XLOOKUP(A6,A5:A604,[1]Sheet3!T294:T893) -> 203.41 | P6: =_xlfn.XLOOKUP(A6,A5:A604,[1]Sheet3!U294:U893) -> 13.82 | Q6: =_xlfn.XLOOKUP(A6,A5:A604,[1]Sheet3!V294:V893) -> 0.067941596 | R6: =_xlfn.XLOOKUP(A6,A5:A604,[1]Sheet3!W294:W893) -> 60.46 | S6: =_xlfn.XLOOKUP(A6,A5:A604,[1]Sheet3!X294:X893) -> Cash on Delivery | T6: =_xlfn.XLOOKUP(A6,A5:A604,[1]Sheet3!Z294:Z893) -> 5 | U6: =_xlfn.XLOOKUP(A6,A5:A604,[1]Sheet3!AA294:AA893) -> FALSE | V6: =_xlfn.XLOOKUP(A6,A5:A604,[1]Sheet3!AC294:AC893) -> Delivered | W6: =_xlfn.XLOOKUP(A6,A5:A604,[1]Sheet3!AE294:AE893) -> 10
A7: ORD-00038 | B7: =_xlfn.XLOOKUP(A7,A6:A605,[1]Sheet3!C253:C852) -> 43844 | C7: =_xlfn.XLOOKUP(A7,A6:A605,[1]Sheet3!D253:D852) -> CUST79223 | D7: =_xlfn.XLOOKUP(A7,A6:A605,[1]Sheet3!E253:E852) -> Sunita Reddy | E7: =_xlfn.XLOOKUP(A7,A6:A605,[1]Sheet3!G253:G852) -> 20 | F7: =_xlfn.XLOOKUP('Retail Sales'!A254,'Retail Sales'!A253:A852,[1]Sheet3!H253:H852) -> Young Adult | G7: =_xlfn.XLOOKUP(A7,A6:A605,[1]Sheet3!J253:J852) -> Male | H7: =_xlfn.XLOOKUP(A7,A6:A605,[1]Sheet3!K253:K852) -> East | I7: =_xlfn.XLOOKUP(A7,A6:A605,[1]Sheet3!L253:L852) -> Kolkata | J7: =_xlfn.XLOOKUP(A7,A6:A605,[1]Sheet3!M253:M852) -> Books | K7: =_xlfn.XLOOKUP('Retail Sales'!A254,'Retail Sales'!A253:A852,[1]Sheet3!N253:N852) -> Fiction Novel | L7: =_xlfn.XLOOKUP(A7,A6:A605,[1]Sheet3!P253:P852) -> 1 | M7: =_xlfn.XLOOKUP(A7,A6:A605,[1]Sheet3!Q253:Q852) -> 1172.06 | N7: =_xlfn.XLOOKUP(A7,A6:A605,[1]Sheet3!S253:S852) -> 0.18 | O7: =_xlfn.XLOOKUP(A7,A6:A605,[1]Sheet3!T253:T852) -> 613.66 | P7: =_xlfn.XLOOKUP(A7,A6:A605,[1]Sheet3!U253:U852) -> 243.99 | Q7: =_xlfn.XLOOKUP(A7,A6:A605,[1]Sheet3!V253:V852) -> 0.39759802 | R7: =_xlfn.XLOOKUP(A7,A6:A605,[1]Sheet3!W253:W852) -> 62.05 | S7: =_xlfn.XLOOKUP(A7,A6:A605,[1]Sheet3!X253:X852) -> Cash on Delivery | T7: =_xlfn.XLOOKUP(A7,A6:A605,[1]Sheet3!Z253:Z852) -> 4 | U7: =_xlfn.XLOOKUP(A7,A6:A605,[1]Sheet3!AA253:AA852) -> FALSE | V7: =_xlfn.XLOOKUP(A7,A6:A605,[1]Sheet3!AC253:AC852) -> Delivered | W7: =_xlfn.XLOOKUP(A7,A6:A605,[1]Sheet3!AE253:AE852) -> 1
A8: ORD-00049 | B8: =_xlfn.XLOOKUP(A8,A7:A606,[1]Sheet3!C20:C619) -> 43849 | C8: =_xlfn.XLOOKUP(A8,A7:A606,[1]Sheet3!D20:D619) -> CUST43401 | D8: =_xlfn.XLOOKUP(A8,A7:A606,[1]Sheet3!E20:E619) -> Sanjay Bose | E8: =_xlfn.XLOOKUP(A8,A7:A606,[1]Sheet3!G20:G619) -> 21 | F8: =_xlfn.XLOOKUP('Retail Sales'!A21,'Retail Sales'!A20:A619,[1]Sheet3!H20:H619) -> Young Adult | G8: =_xlfn.XLOOKUP(A8,A7:A606,[1]Sheet3!J20:J619) -> Other | H8: =_xlfn.XLOOKUP(A8,A7:A606,[1]Sheet3!K20:K619) -> North | I8: =_xlfn.XLOOKUP(A8,A7:A606,[1]Sheet3!L20:L619) -> Delhi | J8: =_xlfn.XLOOKUP(A8,A7:A606,[1]Sheet3!M20:M619) -> Furniture | K8: =_xlfn.XLOOKUP('Retail Sales'!A21,'Retail Sales'!A20:A619,[1]Sheet3!N20:N619) -> Sofa | L8: =_xlfn.XLOOKUP(A8,A7:A606,[1]Sheet3!P20:P619) -> 3 | M8: =_xlfn.XLOOKUP(A8,A7:A606,[1]Sheet3!Q20:Q619) -> 34890.63 | N8: =_xlfn.XLOOKUP(A8,A7:A606,[1]Sheet3!S20:S619) -> 0.29 | O8: =_xlfn.XLOOKUP(A8,A7:A606,[1]Sheet3!T20:T619) -> 64727.53 | P8: =_xlfn.XLOOKUP(A8,A7:A606,[1]Sheet3!U20:U619) -> 18067.63 | Q8: =_xlfn.XLOOKUP(A8,A7:A606,[1]Sheet3!V20:V619) -> 0.27913362 | R8: =_xlfn.XLOOKUP(A8,A7:A606,[1]Sheet3!W20:W619) -> 40.97 | S8: =_xlfn.XLOOKUP(A8,A7:A606,[1]Sheet3!X20:X619) -> Net Banking | T8: =_xlfn.XLOOKUP(A8,A7:A606,[1]Sheet3!Z20:Z619) -> 5 | U8: =_xlfn.XLOOKUP(A8,A7:A606,[1]Sheet3!AA20:AA619) -> FALSE | V8: =_xlfn.XLOOKUP(A8,A7:A606,[1]Sheet3!AC20:AC619) -> Shipped | W8: =_xlfn.XLOOKUP(A8,A7:A606,[1]Sheet3!AE20:AE619) -> 3
A9: ORD-00051 | B9: =_xlfn.XLOOKUP(A9,A8:A607,[1]Sheet3!C586:C1185) -> 43850 | C9: =_xlfn.XLOOKUP(A9,A8:A607,[1]Sheet3!D586:D1185) -> CUST27973 | D9: =_xlfn.XLOOKUP(A9,A8:A607,[1]Sheet3!E586:E1185) -> Shreya Pillai | E9: =_xlfn.XLOOKUP(A9,A8:A607,[1]Sheet3!G586:G1185) -> 13 | F9: =_xlfn.XLOOKUP('Retail Sales'!A587,'Retail Sales'!A586:A1185,[1]Sheet3!H586:H1185) -> Teen | G9: =_xlfn.XLOOKUP(A9,A8:A607,[1]Sheet3!J586:J1185) -> Male | H9: =_xlfn.XLOOKUP(A9,A8:A607,[1]Sheet3!K586:K1185) -> South | I9: =_xlfn.XLOOKUP(A9,A8:A607,[1]Sheet3!L586:L1185) -> Hyderabad | J9: =_xlfn.XLOOKUP(A9,A8:A607,[1]Sheet3!M586:M1185) -> Beauty | K9: =_xlfn.XLOOKUP('Retail Sales'!A587,'Retail Sales'!A586:A1185,[1]Sheet3!N586:N1185) -> Perfume | L9: =_xlfn.XLOOKUP(A9,A8:A607,[1]Sheet3!P586:P1185) -> 6 | M9: =_xlfn.XLOOKUP(A9,A8:A607,[1]Sheet3!Q586:Q1185) -> 1952.59 | N9: =_xlfn.XLOOKUP(A9,A8:A607,[1]Sheet3!S586:S1185) -> 0.14 | O9: =_xlfn.XLOOKUP(A9,A8:A607,[1]Sheet3!T586:T1185) -> 6658.21 | P9: =_xlfn.XLOOKUP(A9,A8:A607,[1]Sheet3!U586:U1185) -> 3867.94 | Q9: =_xlfn.XLOOKUP(A9,A8:A607,[1]Sheet3!V586:V1185) -> 0.58092791 | R9: =_xlfn.XLOOKUP(A9,A8:A607,[1]Sheet3!W586:W1185) -> 38.17 | S9: =_xlfn.XLOOKUP(A9,A8:A607,[1]Sheet3!X586:X1185) -> Credit Card | T9: =_xlfn.XLOOKUP(A9,A8:A607,[1]Sheet3!Z586:Z1185) -> 1 | U9: =_xlfn.XLOOKUP(A9,A8:A607,[1]Sheet3!AA586:AA1185) -> FALSE | V9: =_xlfn.XLOOKUP(A9,A8:A607,[1]Sheet3!AC586:AC1185) -> Shipped | W9: =_xlfn.XLOOKUP(A9,A8:A607,[1]Sheet3!AE586:AE1185) -> 8
A10: ORD-00053 | B10: =_xlfn.XLOOKUP(A10,A9:A608,[1]Sheet3!C211:C810) -> 43851 | C10: =_xlfn.XLOOKUP(A10,A9:A608,[1]Sheet3!D211:D810) -> CUST07190 | D10: =_xlfn.XLOOKUP(A10,A9:A608,[1]Sheet3!E211:E810) -> Deepa Kapoor | E10: =_xlfn.XLOOKUP(A10,A9:A608,[1]Sheet3!G211:G810) -> 33 | F10: =_xlfn.XLOOKUP('Retail Sales'!A212,'Retail Sales'!A211:A810,[1]Sheet3!H211:H810) -> Young Adult | G10: =_xlfn.XLOOKUP(A10,A9:A608,[1]Sheet3!J211:J810) -> Other | H10: =_xlfn.XLOOKUP(A10,A9:A608,[1]Sheet3!K211:K810) -> East | I10: =_xlfn.XLOOKUP(A10,A9:A608,[1]Sheet3!L211:L810) -> Guwahati | J10: =_xlfn.XLOOKUP(A10,A9:A608,[1]Sheet3!M211:M810) -> Beauty | K10: =_xlfn.XLOOKUP('Retail Sales'!A212,'Retail Sales'!A211:A810,[1]Sheet3!N211:N810) -> Lipstick | L10: =_xlfn.XLOOKUP(A10,A9:A608,[1]Sheet3!P211:P810) -> 9 | M10: =_xlfn.XLOOKUP(A10,A9:A608,[1]Sheet3!Q211:Q810) -> 1931.61 | N10: =_xlfn.XLOOKUP(A10,A9:A608,[1]Sheet3!S211:S810) -> 0.35 | O10: =_xlfn.XLOOKUP(A10,A9:A608,[1]Sheet3!T211:T810) -> 10532.18 | P10: =_xlfn.XLOOKUP(A10,A9:A608,[1]Sheet3!U211:U810) -> 5257.88 | Q10: =_xlfn.XLOOKUP(A10,A9:A608,[1]Sheet3!V211:V810) -> 0.49922048 | R10: =_xlfn.XLOOKUP(A10,A9:A608,[1]Sheet3!W211:W810) -> 98.73 | S10: =_xlfn.XLOOKUP(A10,A9:A608,[1]Sheet3!X211:X810) -> Net Banking | T10: =_xlfn.XLOOKUP(A10,A9:A608,[1]Sheet3!Z211:Z810) -> 5 | U10: =_xlfn.XLOOKUP(A10,A9:A608,[1]Sheet3!AA211:AA810) -> FALSE | V10: =_xlfn.XLOOKUP(A10,A9:A608,[1]Sheet3!AC211:AC810) -> Delivered | W10: =_xlfn.XLOOKUP(A10,A9:A608,[1]Sheet3!AE211:AE810) -> 3
A11: ORD-00058 | B11: =_xlfn.XLOOKUP(A11,A10:A609,[1]Sheet3!C79:C678) -> 43852 | C11: =_xlfn.XLOOKUP(A11,A10:A609,[1]Sheet3!D79:D678) -> CUST60127 | D11: =_xlfn.XLOOKUP(A11,A10:A609,[1]Sheet3!E79:E678) -> Ritu Kapoor | E11: =_xlfn.XLOOKUP(A11,A10:A609,[1]Sheet3!G79:G678) -> 16 | F11: =_xlfn.XLOOKUP('Retail Sales'!A80,'Retail Sales'!A79:A678,[1]Sheet3!H79:H678) -> Teen | G11: =_xlfn.XLOOKUP(A11,A10:A609,[1]Sheet3!J79:J678) -> Other | H11: =_xlfn.XLOOKUP(A11,A10:A609,[1]Sheet3!K79:K678) -> South | I11: =_xlfn.XLOOKUP(A11,A10:A609,[1]Sheet3!L79:L678) -> Bangalore | J11: =_xlfn.XLOOKUP(A11,A10:A609,[1]Sheet3!M79:M678) -> Books | K11: =_xlfn.XLOOKUP('Retail Sales'!A80,'Retail Sales'!A79:A678,[1]Sheet3!N79:N678) -> Textbook | L11: =_xlfn.XLOOKUP(A11,A10:A609,[1]Sheet3!P79:P678) -> 4 | M11: =_xlfn.XLOOKUP(A11,A10:A609,[1]Sheet3!Q79:Q678) -> 363.32 | N11: =_xlfn.XLOOKUP(A11,A10:A609,[1]Sheet3!S79:S678) -> 0.07 | O11: =_xlfn.XLOOKUP(A11,A10:A609,[1]Sheet3!T79:T678) -> 1026.5 | P11: =_xlfn.XLOOKUP(A11,A10:A609,[1]Sheet3!U79:U678) -> 410.28 | Q11: =_xlfn.XLOOKUP(A11,A10:A609,[1]Sheet3!V79:V678) -> 0.39968826 | R11: =_xlfn.XLOOKUP(A11,A10:A609,[1]Sheet3!W79:W678) -> 89.93 | S11: =_xlfn.XLOOKUP(A11,A10:A609,[1]Sheet3!X79:X678) -> EMI | T11: =_xlfn.XLOOKUP(A11,A10:A609,[1]Sheet3!Z79:Z678) -> 5 | U11: =_xlfn.XLOOKUP(A11,A10:A609,[1]Sheet3!AA79:AA678) -> FALSE | V11: =_xlfn.XLOOKUP(A11,A10:A609,[1]Sheet3!AC79:AC678) -> Shipped | W11: =_xlfn.XLOOKUP(A11,A10:A609,[1]Sheet3!AE79:AE678) -> 5
A12: ORD-00073 | B12: =_xlfn.XLOOKUP(A12,A11:A610,[1]Sheet3!C147:C746) -> 43858 | C12: =_xlfn.XLOOKUP(A12,A11:A610,[1]Sheet3!D147:D746) -> CUST44662 | D12: =_xlfn.XLOOKUP(A12,A11:A610,[1]Sheet3!E147:E746) -> Ananya Nair | E12: =_xlfn.XLOOKUP(A12,A11:A610,[1]Sheet3!G147:G746) -> 34.294221 | F12: =_xlfn.XLOOKUP('Retail Sales'!A148,'Retail Sales'!A147:A746,[1]Sheet3!H147:H746) -> Young Adult | G12: =_xlfn.XLOOKUP(A12,A11:A610,[1]Sheet3!J147:J746) -> Male | H12: =_xlfn.XLOOKUP(A12,A11:A610,[1]Sheet3!K147:K746) -> North | I12: =_xlfn.XLOOKUP(A12,A11:A610,[1]Sheet3!L147:L746) -> Delhi | J12: =_xlfn.XLOOKUP(A12,A11:A610,[1]Sheet3!M147:M746) -> Sports | K12: =_xlfn.XLOOKUP('Retail Sales'!A148,'Retail Sales'!A147:A746,[1]Sheet3!N147:N746) -> Dumbbells | L12: =_xlfn.XLOOKUP(A12,A11:A610,[1]Sheet3!P147:P746) -> 4 | M12: =_xlfn.XLOOKUP(A12,A11:A610,[1]Sheet3!Q147:Q746) -> 12945.28 | N12: =_xlfn.XLOOKUP(A12,A11:A610,[1]Sheet3!S147:S746) -> 0.13 | O12: =_xlfn.XLOOKUP(A12,A11:A610,[1]Sheet3!T147:T746) -> 31129.56 | P12: =_xlfn.XLOOKUP(A12,A11:A610,[1]Sheet3!U147:U746) -> 7042.29 | Q12: =_xlfn.XLOOKUP(A12,A11:A610,[1]Sheet3!V147:V746) -> 0.22622517 | R12: =_xlfn.XLOOKUP(A12,A11:A610,[1]Sheet3!W147:W746) -> 65.38 | S12: =_xlfn.XLOOKUP(A12,A11:A610,[1]Sheet3!X147:X746) -> Credit Card | T12: =_xlfn.XLOOKUP(A12,A11:A610,[1]Sheet3!Z147:Z746) -> 5 | U12: =_xlfn.XLOOKUP(A12,A11:A610,[1]Sheet3!AA147:AA746) -> FALSE | V12: =_xlfn.XLOOKUP(A12,A11:A610,[1]Sheet3!AC147:AC746) -> Delivered | W12: =_xlfn.XLOOKUP(A12,A11:A610,[1]Sheet3!AE147:AE746) -> 4
A13: ORD-00086 | B13: =_xlfn.XLOOKUP(A13,A12:A611,[1]Sheet3!C119:C718) -> 43864 | C13: =_xlfn.XLOOKUP(A13,A12:A611,[1]Sheet3!D119:D718) -> CUST63884 | D13: =_xlfn.XLOOKUP(A13,A12:A611,[1]Sheet3!E119:E718) -> Amit Das | E13: =_xlfn.XLOOKUP(A13,A12:A611,[1]Sheet3!G119:G718) -> 29 | F13: =_xlfn.XLOOKUP('Retail Sales'!A120,'Retail Sales'!A119:A718,[1]Sheet3!H119:H718) -> Young Adult | G13: =_xlfn.XLOOKUP(A13,A12:A611,[1]Sheet3!J119:J718) -> Female | H13: =_xlfn.XLOOKUP(A13,A12:A611,[1]Sheet3!K119:K718) -> West | I13: =_xlfn.XLOOKUP(A13,A12:A611,[1]Sheet3!L119:L718) -> Ahmedabad | J13: =_xlfn.XLOOKUP(A13,A12:A611,[1]Sheet3!M119:M718) -> Furniture | K13: =_xlfn.XLOOKUP('Retail Sales'!A120,'Retail Sales'!A119:A718,[1]Sheet3!N119:N718) -> Chair | L13: =_xlfn.XLOOKUP(A13,A12:A611,[1]Sheet3!P119:P718) -> 10 | M13: =_xlfn.XLOOKUP(A13,A12:A611,[1]Sheet3!Q119:Q718) -> 9468.07 | N13: =_xlfn.XLOOKUP(A13,A12:A611,[1]Sheet3!S119:S718) -> 0.32 | O13: =_xlfn.XLOOKUP(A13,A12:A611,[1]Sheet3!T119:T718) -> 57174.24 | P13: =_xlfn.XLOOKUP(A13,A12:A611,[1]Sheet3!U119:U718) -> 15202.22 | Q13: =_xlfn.XLOOKUP(A13,A12:A611,[1]Sheet3!V119:V718) -> 0.26589282 | R13: =_xlfn.XLOOKUP(A13,A12:A611,[1]Sheet3!W119:W718) -> 40.98 | S13: =_xlfn.XLOOKUP(A13,A12:A611,[1]Sheet3!X119:X718) -> EMI | T13: =_xlfn.XLOOKUP(A13,A12:A611,[1]Sheet3!Z119:Z718) -> 3 | U13: =_xlfn.XLOOKUP(A13,A12:A611,[1]Sheet3!AA119:AA718) -> FALSE | V13: =_xlfn.XLOOKUP(A13,A12:A611,[1]Sheet3!AC119:AC718) -> Delivered | W13: =_xlfn.XLOOKUP(A13,A12:A611,[1]Sheet3!AE119:AE718) -> 2
A14: ORD-00093 | B14: =_xlfn.XLOOKUP(A14,A13:A612,[1]Sheet3!C529:C1128) -> 43867 | C14: =_xlfn.XLOOKUP(A14,A13:A612,[1]Sheet3!D529:D1128) -> CUST28742 | D14: =_xlfn.XLOOKUP(A14,A13:A612,[1]Sheet3!E529:E1128) -> Kavya Bhat | E14: =_xlfn.XLOOKUP(A14,A13:A612,[1]Sheet3!G529:G1128) -> 38 | F14: =_xlfn.XLOOKUP('Retail Sales'!A530,'Retail Sales'!A529:A1128,[1]Sheet3!H529:H1128) -> Adult | G14: =_xlfn.XLOOKUP(A14,A13:A612,[1]Sheet3!J529:J1128) -> Female | H14: =_xlfn.XLOOKUP(A14,A13:A612,[1]Sheet3!K529:K1128) -> East | I14: =_xlfn.XLOOKUP(A14,A13:A612,[1]Sheet3!L529:L1128) -> Kolkata | J14: =_xlfn.XLOOKUP(A14,A13:A612,[1]Sheet3!M529:M1128) -> Beauty | K14: =_xlfn.XLOOKUP('Retail Sales'!A530,'Retail Sales'!A529:A1128,[1]Sheet3!N529:N1128) -> Hair Oil | L14: =_xlfn.XLOOKUP(A14,A13:A612,[1]Sheet3!P529:P1128) -> 3 | M14: =_xlfn.XLOOKUP(A14,A13:A612,[1]Sheet3!Q529:Q1128) -> 1535.87 | N14: =_xlfn.XLOOKUP(A14,A13:A612,[1]Sheet3!S529:S1128) -> 0.04 | O14: =_xlfn.XLOOKUP(A14,A13:A612,[1]Sheet3!T529:T1128) -> 3186.03 | P14: =_xlfn.XLOOKUP(A14,A13:A612,[1]Sheet3!U529:U1128) -> 1346.8 | Q14: =_xlfn.XLOOKUP(A14,A13:A612,[1]Sheet3!V529:V1128) -> 0.42272044 | R14: =_xlfn.XLOOKUP(A14,A13:A612,[1]Sheet3!W529:W1128) -> 86.51 | S14: =_xlfn.XLOOKUP(A14,A13:A612,[1]Sheet3!X529:X1128) -> Cash on Delivery | T14: =_xlfn.XLOOKUP(A14,A13:A612,[1]Sheet3!Z529:Z1128) -> 5 | U14: =_xlfn.XLOOKUP(A14,A13:A612,[1]Sheet3!AA529:AA1128) -> TRUE | V14: =_xlfn.XLOOKUP(A14,A13:A612,[1]Sheet3!AC529:AC1128) -> Returned | W14: =_xlfn.XLOOKUP(A14,A13:A612,[1]Sheet3!AE529:AE1128) -> 7
A15: ORD-00099 | B15: =_xlfn.XLOOKUP(A15,A14:A613,[1]Sheet3!C69:C668) -> 43869 | C15: =_xlfn.XLOOKUP(A15,A14:A613,[1]Sheet3!D69:D668) -> CUST15599 | D15: =_xlfn.XLOOKUP(A15,A14:A613,[1]Sheet3!E69:E668) -> Karan Shah | E15: =_xlfn.XLOOKUP(A15,A14:A613,[1]Sheet3!G69:G668) -> 33 | F15: =_xlfn.XLOOKUP('Retail Sales'!A70,'Retail Sales'!A69:A668,[1]Sheet3!H69:H668) -> Young Adult | G15: =_xlfn.XLOOKUP(A15,A14:A613,[1]Sheet3!J69:J668) -> Other | H15: =_xlfn.XLOOKUP(A15,A14:A613,[1]Sheet3!K69:K668) -> West | I15: =_xlfn.XLOOKUP(A15,A14:A613,[1]Sheet3!L69:L668) -> Pune | J15: =_xlfn.XLOOKUP(A15,A14:A613,[1]Sheet3!M69:M668) -> Furniture | K15: =_xlfn.XLOOKUP('Retail Sales'!A70,'Retail Sales'!A69:A668,[1]Sheet3!N69:N668) -> Chair | L15: =_xlfn.XLOOKUP(A15,A14:A613,[1]Sheet3!P69:P668) -> 9 | M15: =_xlfn.XLOOKUP(A15,A14:A613,[1]Sheet3!Q69:Q668) -> 22687.65 | N15: =_xlfn.XLOOKUP(A15,A14:A613,[1]Sheet3!S69:S668) -> 0.33 | O15: =_xlfn.XLOOKUP(A15,A14:A613,[1]Sheet3!T69:T668) -> 117568.37 | P15: =_xlfn.XLOOKUP(A15,A14:A613,[1]Sheet3!U69:U668) -> 33050.92 | Q15: =_xlfn.XLOOKUP(A15,A14:A613,[1]Sheet3!V69:V668) -> 0.28112085 | R15: =_xlfn.XLOOKUP(A15,A14:A613,[1]Sheet3!W69:W668) -> 45.04 | S15: =_xlfn.XLOOKUP(A15,A14:A613,[1]Sheet3!X69:X668) -> Net Banking | T15: =_xlfn.XLOOKUP(A15,A14:A613,[1]Sheet3!Z69:Z668) -> 3 | U15: =_xlfn.XLOOKUP(A15,A14:A613,[1]Sheet3!AA69:AA668) -> FALSE | V15: =_xlfn.XLOOKUP(A15,A14:A613,[1]Sheet3!AC69:AC668) -> Delivered | W15: =_xlfn.XLOOKUP(A15,A14:A613,[1]Sheet3!AE69:AE668) -> 2
A16: ORD-00101 | B16: =_xlfn.XLOOKUP(A16,A15:A614,[1]Sheet3!C111:C710) -> 43869 | C16: =_xlfn.XLOOKUP(A16,A15:A614,[1]Sheet3!D111:D710) -> CUST45487 | D16: =_xlfn.XLOOKUP(A16,A15:A614,[1]Sheet3!E111:E710) -> Sunita Joshi | E16: =_xlfn.XLOOKUP(A16,A15:A614,[1]Sheet3!G111:G710) -> 34 | F16: =_xlfn.XLOOKUP('Retail Sales'!A112,'Retail Sales'!A111:A710,[1]Sheet3!H111:H710) -> Young Adult | G16: =_xlfn.XLOOKUP(A16,A15:A614,[1]Sheet3!J111:J710) -> Other | H16: =_xlfn.XLOOKUP(A16,A15:A614,[1]Sheet3!K111:K710) -> West | I16: =_xlfn.XLOOKUP(A16,A15:A614,[1]Sheet3!L111:L710) -> Pune | J16: =_xlfn.XLOOKUP(A16,A15:A614,[1]Sheet3!M111:M710) -> Books | K16: =_xlfn.XLOOKUP('Retail Sales'!A112,'Retail Sales'!A111:A710,[1]Sheet3!N111:N710) -> Cook Book | L16: =_xlfn.XLOOKUP(A16,A15:A614,[1]Sheet3!P111:P710) -> 8 | M16: =_xlfn.XLOOKUP(A16,A15:A614,[1]Sheet3!Q111:Q710) -> 1325.02 | N16: =_xlfn.XLOOKUP(A16,A15:A614,[1]Sheet3!S111:S710) -> 0.09 | O16: =_xlfn.XLOOKUP(A16,A15:A614,[1]Sheet3!T111:T710) -> 8717.89 | P16: =_xlfn.XLOOKUP(A16,A15:A614,[1]Sheet3!U111:U710) -> 3265.49 | Q16: =_xlfn.XLOOKUP(A16,A15:A614,[1]Sheet3!V111:V710) -> 0.37457343 | R16: =_xlfn.XLOOKUP(A16,A15:A614,[1]Sheet3!W111:W710) -> 41.67 | S16: =_xlfn.XLOOKUP(A16,A15:A614,[1]Sheet3!X111:X710) -> Debit Card | T16: =_xlfn.XLOOKUP(A16,A15:A614,[1]Sheet3!Z111:Z710) -> 2 | U16: =_xlfn.XLOOKUP(A16,A15:A614,[1]Sheet3!AA111:AA710) -> FALSE | V16: =_xlfn.XLOOKUP(A16,A15:A614,[1]Sheet3!AC111:AC710) -> Cancelled | W16: =_xlfn.XLOOKUP(A16,A15:A614,[1]Sheet3!AE111:AE710) -> 5
A17: ORD-00105 | B17: =_xlfn.XLOOKUP(A17,A16:A615,[1]Sheet3!C10:C609) -> 43870 | C17: =_xlfn.XLOOKUP(A17,A16:A615,[1]Sheet3!D10:D609) -> CUST75337 | D17: =_xlfn.XLOOKUP(A17,A16:A615,[1]Sheet3!E10:E609) -> Arjun Das | E17: =_xlfn.XLOOKUP(A17,A16:A615,[1]Sheet3!G10:G609) -> 17 | F17: =_xlfn.XLOOKUP('Retail Sales'!A11,'Retail Sales'!A10:A609,[1]Sheet3!H10:H609) -> Teen | G17: =_xlfn.XLOOKUP(A17,A16:A615,[1]Sheet3!J10:J609) -> Female | H17: =_xlfn.XLOOKUP(A17,A16:A615,[1]Sheet3!K10:K609) -> East | I17: =_xlfn.XLOOKUP(A17,A16:A615,[1]Sheet3!L10:L609) -> Patna | J17: =_xlfn.XLOOKUP(A17,A16:A615,[1]Sheet3!M10:M609) -> Clothing | K17: =_xlfn.XLOOKUP('Retail Sales'!A11,'Retail Sales'!A10:A609,[1]Sheet3!N10:N609) -> Kurta | L17: =_xlfn.XLOOKUP(A17,A16:A615,[1]Sheet3!P10:P609) -> 9 | M17: =_xlfn.XLOOKUP(A17,A16:A615,[1]Sheet3!Q10:Q609) -> 2128.77 | N17: =_xlfn.XLOOKUP(A17,A16:A615,[1]Sheet3!S10:S609) -> 0.1 | O17: =_xlfn.XLOOKUP(A17,A16:A615,[1]Sheet3!T10:T609) -> 14568.16 | P17: =_xlfn.XLOOKUP(A17,A16:A615,[1]Sheet3!U10:U609) -> 4173.45 | Q17: =_xlfn.XLOOKUP(A17,A16:A615,[1]Sheet3!V10:V609) -> 0.2864775 | R17: =_xlfn.XLOOKUP(A17,A16:A615,[1]Sheet3!W10:W609) -> 75.33 | S17: =_xlfn.XLOOKUP(A17,A16:A615,[1]Sheet3!X10:X609) -> UPI | T17: =_xlfn.XLOOKUP(A17,A16:A615,[1]Sheet3!Z10:Z609) -> 3 | U17: =_xlfn.XLOOKUP(A17,A16:A615,[1]Sheet3!AA10:AA609) -> FALSE | V17: =_xlfn.XLOOKUP(A17,A16:A615,[1]Sheet3!AC10:AC609) -> Delivered | W17: =_xlfn.XLOOKUP(A17,A16:A615,[1]Sheet3!AE10:AE609) -> 8
A18: ORD-00115 | B18: =_xlfn.XLOOKUP(A18,A17:A616,[1]Sheet3!C459:C1058) -> 43873 | C18: =_xlfn.XLOOKUP(A18,A17:A616,[1]Sheet3!D459:D1058) -> CUST05374 | D18: =_xlfn.XLOOKUP(A18,A17:A616,[1]Sheet3!E459:E1058) -> Aditya Chatterjee | E18: =_xlfn.XLOOKUP(A18,A17:A616,[1]Sheet3!G459:G1058) -> 39 | F18: =_xlfn.XLOOKUP('Retail Sales'!A460,'Retail Sales'!A459:A1058,[1]Sheet3!H459:H1058) -> Adult | G18: =_xlfn.XLOOKUP(A18,A17:A616,[1]Sheet3!J459:J1058) -> Female | H18: =_xlfn.XLOOKUP(A18,A17:A616,[1]Sheet3!K459:K1058) -> South | I18: =_xlfn.XLOOKUP(A18,A17:A616,[1]Sheet3!L459:L1058) -> Chennai | J18: =_xlfn.XLOOKUP(A18,A17:A616,[1]Sheet3!M459:M1058) -> Beauty | K18: =_xlfn.XLOOKUP('Retail Sales'!A460,'Retail Sales'!A459:A1058,[1]Sheet3!N459:N1058) -> Hair Oil | L18: =_xlfn.XLOOKUP(A18,A17:A616,[1]Sheet3!P459:P1058) -> 6 | M18: =_xlfn.XLOOKUP(A18,A17:A616,[1]Sheet3!Q459:Q1058) -> 1270.36 | N18: =_xlfn.XLOOKUP(A18,A17:A616,[1]Sheet3!S459:S1058) -> 0.06 | O18: =_xlfn.XLOOKUP(A18,A17:A616,[1]Sheet3!T459:T1058) -> 5747.77 | P18: =_xlfn.XLOOKUP(A18,A17:A616,[1]Sheet3!U459:U1058) -> 2669 | Q18: =_xlfn.XLOOKUP(A18,A17:A616,[1]Sheet3!V459:V1058) -> 0.464354 | R18: =_xlfn.XLOOKUP(A18,A17:A616,[1]Sheet3!W459:W1058) -> 62.46 | S18: =_xlfn.XLOOKUP(A18,A17:A616,[1]Sheet3!X459:X1058) -> EMI | T18: =_xlfn.XLOOKUP(A18,A17:A616,[1]Sheet3!Z459:Z1058) -> 3 | U18: =_xlfn.XLOOKUP(A18,A17:A616,[1]Sheet3!AA459:AA1058) -> FALSE | V18: =_xlfn.XLOOKUP(A18,A17:A616,[1]Sheet3!AC459:AC1058) -> Delivered | W18: =_xlfn.XLOOKUP(A18,A17:A616,[1]Sheet3!AE459:AE1058) -> 8
A19: ORD-00117 | B19: =_xlfn.XLOOKUP(A19,A18:A617,[1]Sheet3!C60:C659) -> 43873 | C19: =_xlfn.XLOOKUP(A19,A18:A617,[1]Sheet3!D60:D659) -> CUST33188 | D19: =_xlfn.XLOOKUP(A19,A18:A617,[1]Sheet3!E60:E659) -> Sanjay Joshi | E19: =_xlfn.XLOOKUP(A19,A18:A617,[1]Sheet3!G60:G659) -> 48 | F19: =_xlfn.XLOOKUP('Retail Sales'!A61,'Retail Sales'!A60:A659,[1]Sheet3!H60:H659) -> Adult | G19: =_xlfn.XLOOKUP(A19,A18:A617,[1]Sheet3!J60:J659) -> Female | H19: =_xlfn.XLOOKUP(A19,A18:A617,[1]Sheet3!K60:K659) -> South | I19: =_xlfn.XLOOKUP(A19,A18:A617,[1]Sheet3!L60:L659) -> Kochi | J19: =_xlfn.XLOOKUP(A19,A18:A617,[1]Sheet3!M60:M659) -> Sports | K19: =_xlfn.XLOOKUP('Retail Sales'!A61,'Retail Sales'!A60:A659,[1]Sheet3!N60:N659) -> Cycle | L19: =_xlfn.XLOOKUP(A19,A18:A617,[1]Sheet3!P60:P659) -> 3 | M19: =_xlfn.XLOOKUP(A19,A18:A617,[1]Sheet3!Q60:Q659) -> 6047.51 | N19: =_xlfn.XLOOKUP(A19,A18:A617,[1]Sheet3!S60:S659) -> 0.08 | O19: =_xlfn.XLOOKUP(A19,A18:A617,[1]Sheet3!T60:T659) -> 13365.94 | P19: =_xlfn.XLOOKUP(A19,A18:A617,[1]Sheet3!U60:U659) -> 2741.49 | Q19: =_xlfn.XLOOKUP(A19,A18:A617,[1]Sheet3!V60:V659) -> 0.20511015 | R19: =_xlfn.XLOOKUP(A19,A18:A617,[1]Sheet3!W60:W659) -> 36.15 | S19: =_xlfn.XLOOKUP(A19,A18:A617,[1]Sheet3!X60:X659) -> Debit Card | T19: =_xlfn.XLOOKUP(A19,A18:A617,[1]Sheet3!Z60:Z659) -> 4 | U19: =_xlfn.XLOOKUP(A19,A18:A617,[1]Sheet3!AA60:AA659) -> FALSE | V19: =_xlfn.XLOOKUP(A19,A18:A617,[1]Sheet3!AC60:AC659) -> Delivered | W19: =_xlfn.XLOOKUP(A19,A18:A617,[1]Sheet3!AE60:AE659) -> 3
A20: ORD-00129 | B20: =_xlfn.XLOOKUP(A20,A19:A618,[1]Sheet3!C569:C1168) -> 43880 | C20: =_xlfn.XLOOKUP(A20,A19:A618,[1]Sheet3!D569:D1168) -> CUST20302 | D20: =_xlfn.XLOOKUP(A20,A19:A618,[1]Sheet3!E569:E1168) -> Aditya Gupta | E20: =_xlfn.XLOOKUP(A20,A19:A618,[1]Sheet3!G569:G1168) -> 48 | F20: =_xlfn.XLOOKUP('Retail Sales'!A570,'Retail Sales'!A569:A1168,[1]Sheet3!H569:H1168) -> Adult | G20: =_xlfn.XLOOKUP(A20,A19:A618,[1]Sheet3!J569:J1168) -> Other | H20: =_xlfn.XLOOKUP(A20,A19:A618,[1]Sheet3!K569:K1168) -> South | I20: =_xlfn.XLOOKUP(A20,A19:A618,[1]Sheet3!L569:L1168) -> Bangalore | J20: =_xlfn.XLOOKUP(A20,A19:A618,[1]Sheet3!M569:M1168) -> Clothing | K20: =_xlfn.XLOOKUP('Retail Sales'!A570,'Retail Sales'!A569:A1168,[1]Sheet3!N569:N1168) -> Saree | L20: =_xlfn.XLOOKUP(A20,A19:A618,[1]Sheet3!P569:P1168) -> 8 | M20: =_xlfn.XLOOKUP(A20,A19:A618,[1]Sheet3!Q569:Q1168) -> 967.73 | N20: =_xlfn.XLOOKUP(A20,A19:A618,[1]Sheet3!S569:S1168) -> 0.36 | O20: =_xlfn.XLOOKUP(A20,A19:A618,[1]Sheet3!T569:T1168) -> 4117.6 | P20: =_xlfn.XLOOKUP(A20,A19:A618,[1]Sheet3!U569:U1168) -> 1596.92 | Q20: =_xlfn.XLOOKUP(A20,A19:A618,[1]Sheet3!V569:V1168) -> 0.38782786 | R20: =_xlfn.XLOOKUP(A20,A19:A618,[1]Sheet3!W569:W1168) -> 73.93 | S20: =_xlfn.XLOOKUP(A20,A19:A618,[1]Sheet3!X569:X1168) -> Credit Card | T20: =_xlfn.XLOOKUP(A20,A19:A618,[1]Sheet3!Z569:Z1168) -> 3 | U20: =_xlfn.XLOOKUP(A20,A19:A618,[1]Sheet3!AA569:AA1168) -> TRUE | V20: =_xlfn.XLOOKUP(A20,A19:A618,[1]Sheet3!AC569:AC1168) -> Returned | W20: =_xlfn.XLOOKUP(A20,A19:A618,[1]Sheet3!AE569:AE1168) -> 6
A21: ORD-00130 | B21: =_xlfn.XLOOKUP(A21,A20:A619,[1]Sheet3!C331:C930) -> 43881 | C21: =_xlfn.XLOOKUP(A21,A20:A619,[1]Sheet3!D331:D930) -> CUST73625 | D21: =_xlfn.XLOOKUP(A21,A20:A619,[1]Sheet3!E331:E930) -> Nisha Bose | E21: =_xlfn.XLOOKUP(A21,A20:A619,[1]Sheet3!G331:G930) -> 28 | F21: =_xlfn.XLOOKUP('Retail Sales'!A332,'Retail Sales'!A331:A930,[1]Sheet3!H331:H930) -> Young Adult | G21: =_xlfn.XLOOKUP(A21,A20:A619,[1]Sheet3!J331:J930) -> Other | H21: =_xlfn.XLOOKUP(A21,A20:A619,[1]Sheet3!K331:K930) -> East | I21: =_xlfn.XLOOKUP(A21,A20:A619,[1]Sheet3!L331:L930) -> Guwahati | J21: =_xlfn.XLOOKUP(A21,A20:A619,[1]Sheet3!M331:M930) -> Books | K21: =_xlfn.XLOOKUP('Retail Sales'!A332,'Retail Sales'!A331:A930,[1]Sheet3!N331:N930) -> Textbook | L21: =_xlfn.XLOOKUP(A21,A20:A619,[1]Sheet3!P331:P930) -> 10 | M21: =_xlfn.XLOOKUP(A21,A20:A619,[1]Sheet3!Q331:Q930) -> 327.54 | N21: =_xlfn.XLOOKUP(A21,A20:A619,[1]Sheet3!S331:S930) -> 0.15 | O21: =_xlfn.XLOOKUP(A21,A20:A619,[1]Sheet3!T331:T930) -> 2755.17 | P21: =_xlfn.XLOOKUP(A21,A20:A619,[1]Sheet3!U331:U930) -> 1528.85 | Q21: =_xlfn.XLOOKUP(A21,A20:A619,[1]Sheet3!V331:V930) -> 0.55490224 | R21: =_xlfn.XLOOKUP(A21,A20:A619,[1]Sheet3!W331:W930) -> 80.58 | S21: =_xlfn.XLOOKUP(A21,A20:A619,[1]Sheet3!X331:X930) -> Debit Card | T21: =_xlfn.XLOOKUP(A21,A20:A619,[1]Sheet3!Z331:Z930) -> 5 | U21: =_xlfn.XLOOKUP(A21,A20:A619,[1]Sheet3!AA331:AA930) -> TRUE | V21: =_xlfn.XLOOKUP(A21,A20:A619,[1]Sheet3!AC331:AC930) -> Returned | W21: =_xlfn.XLOOKUP(A21,A20:A619,[1]Sheet3!AE331:AE930) -> 2
A22: ORD-00132 | B22: =_xlfn.XLOOKUP(A22,A21:A620,[1]Sheet3!C347:C946) -> 43881 | C22: =_xlfn.XLOOKUP(A22,A21:A620,[1]Sheet3!D347:D946) -> CUST20387 | D22: =_xlfn.XLOOKUP(A22,A21:A620,[1]Sheet3!E347:E946) -> Ritu Mishra | E22: =_xlfn.XLOOKUP(A22,A21:A620,[1]Sheet3!G347:G946) -> 26 | F22: =_xlfn.XLOOKUP('Retail Sales'!A348,'Retail Sales'!A347:A946,[1]Sheet3!H347:H946) -> Young Adult | G22: =_xlfn.XLOOKUP(A22,A21:A620,[1]Sheet3!J347:J946) -> Female | H22: =_xlfn.XLOOKUP(A22,A21:A620,[1]Sheet3!K347:K946) -> South | I22: =_xlfn.XLOOKUP(A22,A21:A620,[1]Sheet3!L347:L946) -> Kochi | J22: =_xlfn.XLOOKUP(A22,A21:A620,[1]Sheet3!M347:M946) -> Beauty | K22: =_xlfn.XLOOKUP('Retail Sales'!A348,'Retail Sales'!A347:A946,[1]Sheet3!N347:N946) -> Lipstick | L22: =_xlfn.XLOOKUP(A22,A21:A620,[1]Sheet3!P347:P946) -> 2 | M22: =_xlfn.XLOOKUP(A22,A21:A620,[1]Sheet3!Q347:Q946) -> 959.97 | N22: =_xlfn.XLOOKUP(A22,A21:A620,[1]Sheet3!S347:S946) -> 0.05 | O22: =_xlfn.XLOOKUP(A22,A21:A620,[1]Sheet3!T347:T946) -> 1563.91 | P22: =_xlfn.XLOOKUP(A22,A21:A620,[1]Sheet3!U347:U946) -> 630.51 | Q22: =_xlfn.XLOOKUP(A22,A21:A620,[1]Sheet3!V347:V946) -> 0.40316259 | R22: =_xlfn.XLOOKUP(A22,A21:A620,[1]Sheet3!W347:W946) -> 71.85 | S22: =_xlfn.XLOOKUP(A22,A21:A620,[1]Sheet3!X347:X946) -> EMI | T22: =_xlfn.XLOOKUP(A22,A21:A620,[1]Sheet3!Z347:Z946) -> 4 | U22: =_xlfn.XLOOKUP(A22,A21:A620,[1]Sheet3!AA347:AA946) -> FALSE | V22: =_xlfn.XLOOKUP(A22,A21:A620,[1]Sheet3!AC347:AC946) -> Delivered | W22: =_xlfn.XLOOKUP(A22,A21:A620,[1]Sheet3!AE347:AE946) -> 2
A23: ORD-00138 | B23: =_xlfn.XLOOKUP(A23,A22:A621,[1]Sheet3!C497:C1096) -> 43885 | C23: =_xlfn.XLOOKUP(A23,A22:A621,[1]Sheet3!D497:D1096) -> CUST54691 | D23: =_xlfn.XLOOKUP(A23,A22:A621,[1]Sheet3!E497:E1096) -> Priya Shah | E23: =_xlfn.XLOOKUP(A23,A22:A621,[1]Sheet3!G497:G1096) -> 27 | F23: =_xlfn.XLOOKUP('Retail Sales'!A498,'Retail Sales'!A497:A1096,[1]Sheet3!H497:H1096) -> Young Adult | G23: =_xlfn.XLOOKUP(A23,A22:A621,[1]Sheet3!J497:J1096) -> Female | H23: =_xlfn.XLOOKUP(A23,A22:A621,[1]Sheet3!K497:K1096) -> East | I23: =_xlfn.XLOOKUP(A23,A22:A621,[1]Sheet3!L497:L1096) -> Patna | J23: =_xlfn.XLOOKUP(A23,A22:A621,[1]Sheet3!M497:M1096) -> Beauty | K23: =_xlfn.XLOOKUP('Retail Sales'!A498,'Retail Sales'!A497:A1096,[1]Sheet3!N497:N1096) -> Sunscreen | L23: =_xlfn.XLOOKUP(A23,A22:A621,[1]Sheet3!P497:P1096) -> 3 | M23: =_xlfn.XLOOKUP(A23,A22:A621,[1]Sheet3!Q497:Q1096) -> 1655.54 | N23: =_xlfn.XLOOKUP(A23,A22:A621,[1]Sheet3!S497:S1096) -> 0.25 | O23: =_xlfn.XLOOKUP(A23,A22:A621,[1]Sheet3!T497:T1096) -> 2825.92 | P23: =_xlfn.XLOOKUP(A23,A22:A621,[1]Sheet3!U497:U1096) -> 1777.23 | Q23: =_xlfn.XLOOKUP(A23,A22:A621,[1]Sheet3!V497:V1096) -> 0.62890315 | R23: =_xlfn.XLOOKUP(A23,A22:A621,[1]Sheet3!W497:W1096) -> 81.69 | S23: =_xlfn.XLOOKUP(A23,A22:A621,[1]Sheet3!X497:X1096) -> UPI | T23: =_xlfn.XLOOKUP(A23,A22:A621,[1]Sheet3!Z497:Z1096) -> 3 | U23: =_xlfn.XLOOKUP(A23,A22:A621,[1]Sheet3!AA497:AA1096) -> FALSE | V23: =_xlfn.XLOOKUP(A23,A22:A621,[1]Sheet3!AC497:AC1096) -> Delivered | W23: =_xlfn.XLOOKUP(A23,A22:A621,[1]Sheet3!AE497:AE1096) -> 5
A24: ORD-00142 | B24: =_xlfn.XLOOKUP(A24,A23:A622,[1]Sheet3!C395:C994) -> 43888 | C24: =_xlfn.XLOOKUP(A24,A23:A622,[1]Sheet3!D395:D994) -> CUST82516 | D24: =_xlfn.XLOOKUP(A24,A23:A622,[1]Sheet3!E395:E994) -> Ritu Joshi | E24: =_xlfn.XLOOKUP(A24,A23:A622,[1]Sheet3!G395:G994) -> 40 | F24: =_xlfn.XLOOKUP('Retail Sales'!A396,'Retail Sales'!A395:A994,[1]Sheet3!H395:H994) -> Adult | G24: =_xlfn.XLOOKUP(A24,A23:A622,[1]Sheet3!J395:J994) -> Female | H24: =_xlfn.XLOOKUP(A24,A23:A622,[1]Sheet3!K395:K994) -> East | I24: =_xlfn.XLOOKUP(A24,A23:A622,[1]Sheet3!L395:L994) -> Bhubaneswar | J24: =_xlfn.XLOOKUP(A24,A23:A622,[1]Sheet3!M395:M994) -> Sports | K24: =_xlfn.XLOOKUP('Retail Sales'!A396,'Retail Sales'!A395:A994,[1]Sheet3!N395:N994) -> Tennis Racket | L24: =_xlfn.XLOOKUP(A24,A23:A622,[1]Sheet3!P395:P994) -> 1 | M24: =_xlfn.XLOOKUP(A24,A23:A622,[1]Sheet3!Q395:Q994) -> 11227.96 | N24: =_xlfn.XLOOKUP(A24,A23:A622,[1]Sheet3!S395:S994) -> 0.31 | O24: =_xlfn.XLOOKUP(A24,A23:A622,[1]Sheet3!T395:T994) -> 6220.68 | P24: =_xlfn.XLOOKUP(A24,A23:A622,[1]Sheet3!U395:U994) -> 1706.13 | Q24: =_xlfn.XLOOKUP(A24,A23:A622,[1]Sheet3!V395:V994) -> 0.27426744 | R24: =_xlfn.XLOOKUP(A24,A23:A622,[1]Sheet3!W395:W994) -> 87.6 | S24: =_xlfn.XLOOKUP(A24,A23:A622,[1]Sheet3!X395:X994) -> Net Banking | T24: =_xlfn.XLOOKUP(A24,A23:A622,[1]Sheet3!Z395:Z994) -> 2 | U24: =_xlfn.XLOOKUP(A24,A23:A622,[1]Sheet3!AA395:AA994) -> FALSE | V24: =_xlfn.XLOOKUP(A24,A23:A622,[1]Sheet3!AC395:AC994) -> Shipped | W24: =_xlfn.XLOOKUP(A24,A23:A622,[1]Sheet3!AE395:AE994) -> 3
A25: ORD-00158 | B25: =_xlfn.XLOOKUP(A25,A24:A623,[1]Sheet3!C99:C698) -> 43897 | C25: =_xlfn.XLOOKUP(A25,A24:A623,[1]Sheet3!D99:D698) -> CUST56042 | D25: =_xlfn.XLOOKUP(A25,A24:A623,[1]Sheet3!E99:E698) -> Deepa Rao | E25: =_xlfn.XLOOKUP(A25,A24:A623,[1]Sheet3!G99:G698) -> 35 | F25: =_xlfn.XLOOKUP('Retail Sales'!A100,'Retail Sales'!A99:A698,[1]Sheet3!H99:H698) -> Young Adult | G25: =_xlfn.XLOOKUP(A25,A24:A623,[1]Sheet3!J99:J698) -> Female | H25: =_xlfn.XLOOKUP(A25,A24:A623,[1]Sheet3!K99:K698) -> East | I25: =_xlfn.XLOOKUP(A25,A24:A623,[1]Sheet3!L99:L698) -> Bhubaneswar | J25: =_xlfn.XLOOKUP(A25,A24:A623,[1]Sheet3!M99:M698) -> Furniture | K25: =_xlfn.XLOOKUP('Retail Sales'!A100,'Retail Sales'!A99:A698,[1]Sheet3!N99:N698) -> Desk | L25: =_xlfn.XLOOKUP(A25,A24:A623,[1]Sheet3!P99:P698) -> 8 | M25: =_xlfn.XLOOKUP(A25,A24:A623,[1]Sheet3!Q99:Q698) -> 25624.31 | N25: =_xlfn.XLOOKUP(A25,A24:A623,[1]Sheet3!S99:S698) -> 0.12 | O25: =_xlfn.XLOOKUP(A25,A24:A623,[1]Sheet3!T99:T698) -> 188109.47 | P25: =_xlfn.XLOOKUP(A25,A24:A623,[1]Sheet3!U99:U698) -> 45753.79 | Q25: =_xlfn.XLOOKUP(A25,A24:A623,[1]Sheet3!V99:V698) -> 0.24322959 | R25: =_xlfn.XLOOKUP(A25,A24:A623,[1]Sheet3!W99:W698) -> 65.63 | S25: =_xlfn.XLOOKUP(A25,A24:A623,[1]Sheet3!X99:X698) -> Credit Card | T25: =_xlfn.XLOOKUP(A25,A24:A623,[1]Sheet3!Z99:Z698) -> 1 | U25: =_xlfn.XLOOKUP(A25,A24:A623,[1]Sheet3!AA99:AA698) -> FALSE | V25: =_xlfn.XLOOKUP(A25,A24:A623,[1]Sheet3!AC99:AC698) -> Delivered | W25: =_xlfn.XLOOKUP(A25,A24:A623,[1]Sheet3!AE99:AE698) -> 3
A26: ORD-00164 | B26: =_xlfn.XLOOKUP(A26,A25:A624,[1]Sheet3!C514:C1113) -> 43902 | C26: =_xlfn.XLOOKUP(A26,A25:A624,[1]Sheet3!D514:D1113) -> CUST97663 | D26: =_xlfn.XLOOKUP(A26,A25:A624,[1]Sheet3!E514:E1113) -> Aarav Singh | E26: =_xlfn.XLOOKUP(A26,A25:A624,[1]Sheet3!G514:G1113) -> 34.294221 | F26: =_xlfn.XLOOKUP('Retail Sales'!A515,'Retail Sales'!A514:A1113,[1]Sheet3!H514:H1113) -> Young Adult | G26: =_xlfn.XLOOKUP(A26,A25:A624,[1]Sheet3!J514:J1113) -> Male | H26: =_xlfn.XLOOKUP(A26,A25:A624,[1]Sheet3!K514:K1113) -> North | I26: =_xlfn.XLOOKUP(A26,A25:A624,[1]Sheet3!L514:L1113) -> Ludhiana | J26: =_xlfn.XLOOKUP(A26,A25:A624,[1]Sheet3!M514:M1113) -> Clothing | K26: =_xlfn.XLOOKUP('Retail Sales'!A515,'Retail Sales'!A514:A1113,[1]Sheet3!N514:N1113) -> Kurta | L26: =_xlfn.XLOOKUP(A26,A25:A624,[1]Sheet3!P514:P1113) -> 9 | M26: =_xlfn.XLOOKUP(A26,A25:A624,[1]Sheet3!Q514:Q1113) -> 3971.91 | N26: =_xlfn.XLOOKUP(A26,A25:A624,[1]Sheet3!S514:S1113) -> 0.18 | O26: =_xlfn.XLOOKUP(A26,A25:A624,[1]Sheet3!T514:T1113) -> 32366.71 | P26: =_xlfn.XLOOKUP(A26,A25:A624,[1]Sheet3!U514:U1113) -> 14702.14 | Q26: =_xlfn.XLOOKUP(A26,A25:A624,[1]Sheet3!V514:V1113) -> 0.45423647 | R26: =_xlfn.XLOOKUP(A26,A25:A624,[1]Sheet3!W514:W1113) -> 47.38 | S26: =_xlfn.XLOOKUP(A26,A25:A624,[1]Sheet3!X514:X1113) -> Cash on Delivery | T26: =_xlfn.XLOOKUP(A26,A25:A624,[1]Sheet3!Z514:Z1113) -> 3 | U26: =_xlfn.XLOOKUP(A26,A25:A624,[1]Sheet3!AA514:AA1113) -> FALSE | V26: =_xlfn.XLOOKUP(A26,A25:A624,[1]Sheet3!AC514:AC1113) -> Pending | W26: =_xlfn.XLOOKUP(A26,A25:A624,[1]Sheet3!AE514:AE1113) -> 4
A27: ORD-00170 | B27: =_xlfn.XLOOKUP(A27,A26:A625,[1]Sheet3!C268:C867) -> 43905 | C27: =_xlfn.XLOOKUP(A27,A26:A625,[1]Sheet3!D268:D867) -> CUST53622 | D27: =_xlfn.XLOOKUP(A27,A26:A625,[1]Sheet3!E268:E867) -> Aditya Chatterjee | E27: =_xlfn.XLOOKUP(A27,A26:A625,[1]Sheet3!G268:G867) -> 31 | F27: =_xlfn.XLOOKUP('Retail Sales'!A269,'Retail Sales'!A268:A867,[1]Sheet3!H268:H867) -> Young Adult | G27: =_xlfn.XLOOKUP(A27,A26:A625,[1]Sheet3!J268:J867) -> Male | H27: =_xlfn.XLOOKUP(A27,A26:A625,[1]Sheet3!K268:K867) -> South | I27: =_xlfn.XLOOKUP(A27,A26:A625,[1]Sheet3!L268:L867) -> Bangalore | J27: =_xlfn.XLOOKUP(A27,A26:A625,[1]Sheet3!M268:M867) -> Groceries | K27: =_xlfn.XLOOKUP('Retail Sales'!A269,'Retail Sales'!A268:A867,[1]Sheet3!N268:N867) -> Sugar | L27: =_xlfn.XLOOKUP(A27,A26:A625,[1]Sheet3!P268:P867) -> 9 | M27: =_xlfn.XLOOKUP(A27,A26:A625,[1]Sheet3!Q268:Q867) -> 236.54 | N27: =_xlfn.XLOOKUP(A27,A26:A625,[1]Sheet3!S268:S867) -> 0.19 | O27: =_xlfn.XLOOKUP(A27,A26:A625,[1]Sheet3!T268:T867) -> 1658.66 | P27: =_xlfn.XLOOKUP(A27,A26:A625,[1]Sheet3!U268:U867) -> 140.16 | Q27: =_xlfn.XLOOKUP(A27,A26:A625,[1]Sheet3!V268:V867) -> 0.084501947 | R27: =_xlfn.XLOOKUP(A27,A26:A625,[1]Sheet3!W268:W867) -> 101.07 | S27: =_xlfn.XLOOKUP(A27,A26:A625,[1]Sheet3!X268:X867) -> Credit Card | T27: =_xlfn.XLOOKUP(A27,A26:A625,[1]Sheet3!Z268:Z867) -> 3 | U27: =_xlfn.XLOOKUP(A27,A26:A625,[1]Sheet3!AA268:AA867) -> TRUE | V27: =_xlfn.XLOOKUP(A27,A26:A625,[1]Sheet3!AC268:AC867) -> Returned | W27: =_xlfn.XLOOKUP(A27,A26:A625,[1]Sheet3!AE268:AE867) -> 1
A28: ORD-00172 | B28: =_xlfn.XLOOKUP(A28,A27:A626,[1]Sheet3!C450:C1049) -> 43905 | C28: =_xlfn.XLOOKUP(A28,A27:A626,[1]Sheet3!D450:D1049) -> CUST40704 | D28: =_xlfn.XLOOKUP(A28,A27:A626,[1]Sheet3!E450:E1049) -> Aarav Rao | E28: =_xlfn.XLOOKUP(A28,A27:A626,[1]Sheet3!G450:G1049) -> 16 | F28: =_xlfn.XLOOKUP('Retail Sales'!A451,'Retail Sales'!A450:A1049,[1]Sheet3!H450:H1049) -> Teen | G28: =_xlfn.XLOOKUP(A28,A27:A626,[1]Sheet3!J450:J1049) -> Other | H28: =_xlfn.XLOOKUP(A28,A27:A626,[1]Sheet3!K450:K1049) -> East | I28: =_xlfn.XLOOKUP(A28,A27:A626,[1]Sheet3!L450:L1049) -> Guwahati | J28: =_xlfn.XLOOKUP(A28,A27:A626,[1]Sheet3!M450:M1049) -> Clothing | K28: =_xlfn.XLOOKUP('Retail Sales'!A451,'Retail Sales'!A450:A1049,[1]Sheet3!N450:N1049) -> Saree | L28: =_xlfn.XLOOKUP(A28,A27:A626,[1]Sheet3!P450:P1049) -> 2 | M28: =_xlfn.XLOOKUP(A28,A27:A626,[1]Sheet3!Q450:Q1049) -> 2448.31 | N28: =_xlfn.XLOOKUP(A28,A27:A626,[1]Sheet3!S450:S1049) -> 0.35 | O28: =_xlfn.XLOOKUP(A28,A27:A626,[1]Sheet3!T450:T1049) -> 3584.88 | P28: =_xlfn.XLOOKUP(A28,A27:A626,[1]Sheet3!U450:U1049) -> 1270.16 | Q28: =_xlfn.XLOOKUP(A28,A27:A626,[1]Sheet3!V450:V1049) -> 0.35431033 | R28: =_xlfn.XLOOKUP(A28,A27:A626,[1]Sheet3!W450:W1049) -> 79.97 | S28: =_xlfn.XLOOKUP(A28,A27:A626,[1]Sheet3!X450:X1049) -> Credit Card | T28: =_xlfn.XLOOKUP(A28,A27:A626,[1]Sheet3!Z450:Z1049) -> 4 | U28: =_xlfn.XLOOKUP(A28,A27:A626,[1]Sheet3!AA450:AA1049) -> FALSE | V28: =_xlfn.XLOOKUP(A28,A27:A626,[1]Sheet3!AC450:AC1049) -> Delivered | W28: =_xlfn.XLOOKUP(A28,A27:A626,[1]Sheet3!AE450:AE1049) -> 7
A29: ORD-00183 | B29: =_xlfn.XLOOKUP(A29,A28:A627,[1]Sheet3!C222:C821) -> 43912 | C29: =_xlfn.XLOOKUP(A29,A28:A627,[1]Sheet3!D222:D821) -> CUST16395 | D29: =_xlfn.XLOOKUP(A29,A28:A627,[1]Sheet3!E222:E821) -> Sunita Pillai | E29: =_xlfn.XLOOKUP(A29,A28:A627,[1]Sheet3!G222:G821) -> 19 | F29: =_xlfn.XLOOKUP('Retail Sales'!A223,'Retail Sales'!A222:A821,[1]Sheet3!H222:H821) -> Teen | G29: =_xlfn.XLOOKUP(A29,A28:A627,[1]Sheet3!J222:J821) -> Other | H29: =_xlfn.XLOOKUP(A29,A28:A627,[1]Sheet3!K222:K821) -> Central | I29: =_xlfn.XLOOKUP(A29,A28:A627,[1]Sheet3!L222:L821) -> Raipur | J29: =_xlfn.XLOOKUP(A29,A28:A627,[1]Sheet3!M222:M821) -> Beauty | K29: =_xlfn.XLOOKUP('Retail Sales'!A223,'Retail Sales'!A222:A821,[1]Sheet3!N222:N821) -> Sunscreen | L29: =_xlfn.XLOOKUP(A29,A28:A627,[1]Sheet3!P222:P821) -> 9 | M29: =_xlfn.XLOOKUP(A29,A28:A627,[1]Sheet3!Q222:Q821) -> 646.01 | N29: =_xlfn.XLOOKUP(A29,A28:A627,[1]Sheet3!S222:S821) -> 0.38 | O29: =_xlfn.XLOOKUP(A29,A28:A627,[1]Sheet3!T222:T821) -> 3807.56 | P29: =_xlfn.XLOOKUP(A29,A28:A627,[1]Sheet3!U222:U821) -> 1281.84 | Q29: =_xlfn.XLOOKUP(A29,A28:A627,[1]Sheet3!V222:V821) -> 0.33665655 | R29: =_xlfn.XLOOKUP(A29,A28:A627,[1]Sheet3!W222:W821) -> 51.72 | S29: =_xlfn.XLOOKUP(A29,A28:A627,[1]Sheet3!X222:X821) -> Credit Card | T29: =_xlfn.XLOOKUP(A29,A28:A627,[1]Sheet3!Z222:Z821) -> 2 | U29: =_xlfn.XLOOKUP(A29,A28:A627,[1]Sheet3!AA222:AA821) -> FALSE | V29: =_xlfn.XLOOKUP(A29,A28:A627,[1]Sheet3!AC222:AC821) -> Pending | W29: =_xlfn.XLOOKUP(A29,A28:A627,[1]Sheet3!AE222:AE821) -> 3
A30: ORD-00197 | B30: =_xlfn.XLOOKUP(A30,A29:A628,[1]Sheet3!C360:C959) -> 43918 | C30: =_xlfn.XLOOKUP(A30,A29:A628,[1]Sheet3!D360:D959) -> CUST04223 | D30: =_xlfn.XLOOKUP(A30,A29:A628,[1]Sheet3!E360:E959) -> Pooja Joshi | E30: =_xlfn.XLOOKUP(A30,A29:A628,[1]Sheet3!G360:G959) -> 12 | F30: =_xlfn.XLOOKUP('Retail Sales'!A361,'Retail Sales'!A360:A959,[1]Sheet3!H360:H959) -> Child | G30: =_xlfn.XLOOKUP(A30,A29:A628,[1]Sheet3!J360:J959) -> Other | H30: =_xlfn.XLOOKUP(A30,A29:A628,[1]Sheet3!K360:K959) -> North | I30: =_xlfn.XLOOKUP(A30,A29:A628,[1]Sheet3!L360:L959) -> Amritsar | J30: =_xlfn.XLOOKUP(A30,A29:A628,[1]Sheet3!M360:M959) -> Sports | K30: =_xlfn.XLOOKUP('Retail Sales'!A361,'Retail Sales'!A360:A959,[1]Sheet3!N360:N959) -> Cycle | L30: =_xlfn.XLOOKUP(A30,A29:A628,[1]Sheet3!P360:P959) -> 8 | M30: =_xlfn.XLOOKUP(A30,A29:A628,[1]Sheet3!Q360:Q959) -> 10282.68 | N30: =_xlfn.XLOOKUP(A30,A29:A628,[1]Sheet3!S360:S959) -> 0.11 | O30: =_xlfn.XLOOKUP(A30,A29:A628,[1]Sheet3!T360:T959) -> 66340.96 | P30: =_xlfn.XLOOKUP(A30,A29:A628,[1]Sheet3!U360:U959) -> 13106.07 | Q30: =_xlfn.XLOOKUP(A30,A29:A628,[1]Sheet3!V360:V959) -> 0.19755623 | R30: =_xlfn.XLOOKUP(A30,A29:A628,[1]Sheet3!W360:W959) -> 65.44 | S30: =_xlfn.XLOOKUP(A30,A29:A628,[1]Sheet3!X360:X959) -> Net Banking | T30: =_xlfn.XLOOKUP(A30,A29:A628,[1]Sheet3!Z360:Z959) -> 1 | U30: =_xlfn.XLOOKUP(A30,A29:A628,[1]Sheet3!AA360:AA959) -> FALSE | V30: =_xlfn.XLOOKUP(A30,A29:A628,[1]Sheet3!AC360:AC959) -> Delivered | W30: =_xlfn.XLOOKUP(A30,A29:A628,[1]Sheet3!AE360:AE959) -> 3
A31: ORD-00200 | B31: =_xlfn.XLOOKUP(A31,A30:A629,[1]Sheet3!C233:C832) -> 43920 | C31: =_xlfn.XLOOKUP(A31,A30:A629,[1]Sheet3!D233:D832) -> CUST79644 | D31: =_xlfn.XLOOKUP(A31,A30:A629,[1]Sheet3!E233:E832) -> Aarav Verma | E31: =_xlfn.XLOOKUP(A31,A30:A629,[1]Sheet3!G233:G832) -> 23 | F31: =_xlfn.XLOOKUP('Retail Sales'!A234,'Retail Sales'!A233:A832,[1]Sheet3!H233:H832) -> Young Adult | G31: =_xlfn.XLOOKUP(A31,A30:A629,[1]Sheet3!J233:J832) -> Female | H31: =_xlfn.XLOOKUP(A31,A30:A629,[1]Sheet3!K233:K832) -> West | I31: =_xlfn.XLOOKUP(A31,A30:A629,[1]Sheet3!L233:L832) -> Mumbai | J31: =_xlfn.XLOOKUP(A31,A30:A629,[1]Sheet3!M233:M832) -> Sports | K31: =_xlfn.XLOOKUP('Retail Sales'!A234,'Retail Sales'!A233:A832,[1]Sheet3!N233:N832) -> Cycle | L31: =_xlfn.XLOOKUP(A31,A30:A629,[1]Sheet3!P233:P832) -> 5 | M31: =_xlfn.XLOOKUP(A31,A30:A629,[1]Sheet3!Q233:Q832) -> 9009.65 | N31: =_xlfn.XLOOKUP(A31,A30:A629,[1]Sheet3!S233:S832) -> 0.08 | O31: =_xlfn.XLOOKUP(A31,A30:A629,[1]Sheet3!T233:T832) -> 44971.39 | P31: =_xlfn.XLOOKUP(A31,A30:A629,[1]Sheet3!U233:U832) -> 10004.34 | Q31: =_xlfn.XLOOKUP(A31,A30:A629,[1]Sheet3!V233:V832) -> 0.2224601 | R31: =_xlfn.XLOOKUP(A31,A30:A629,[1]Sheet3!W233:W832) -> 58.16 | S31: =_xlfn.XLOOKUP(A31,A30:A629,[1]Sheet3!X233:X832) -> EMI | T31: =_xlfn.XLOOKUP(A31,A30:A629,[1]Sheet3!Z233:Z832) -> 3 | U31: =_xlfn.XLOOKUP(A31,A30:A629,[1]Sheet3!AA233:AA832) -> FALSE | V31: =_xlfn.XLOOKUP(A31,A30:A629,[1]Sheet3!AC233:AC832) -> Delivered | W31: =_xlfn.XLOOKUP(A31,A30:A629,[1]Sheet3!AE233:AE832) -> 4
A32: ORD-00201 | B32: =_xlfn.XLOOKUP(A32,A31:A630,[1]Sheet3!C537:C1136) -> 43920 | C32: =_xlfn.XLOOKUP(A32,A31:A630,[1]Sheet3!D537:D1136) -> CUST39806 | D32: =_xlfn.XLOOKUP(A32,A31:A630,[1]Sheet3!E537:E1136) -> Sanjay Bhat | E32: =_xlfn.XLOOKUP(A32,A31:A630,[1]Sheet3!G537:G1136) -> 27 | F32: =_xlfn.XLOOKUP('Retail Sales'!A538,'Retail Sales'!A537:A1136,[1]Sheet3!H537:H1136) -> Young Adult | G32: =_xlfn.XLOOKUP(A32,A31:A630,[1]Sheet3!J537:J1136) -> Other | H32: =_xlfn.XLOOKUP(A32,A31:A630,[1]Sheet3!K537:K1136) -> West | I32: =_xlfn.XLOOKUP(A32,A31:A630,[1]Sheet3!L537:L1136) -> Mumbai | J32: =_xlfn.XLOOKUP(A32,A31:A630,[1]Sheet3!M537:M1136) -> Beauty | K32: =_xlfn.XLOOKUP('Retail Sales'!A538,'Retail Sales'!A537:A1136,[1]Sheet3!N537:N1136) -> Face Cream | L32: =_xlfn.XLOOKUP(A32,A31:A630,[1]Sheet3!P537:P1136) -> 4 | M32: =_xlfn.XLOOKUP(A32,A31:A630,[1]Sheet3!Q537:Q1136) -> 2430.1 | N32: =_xlfn.XLOOKUP(A32,A31:A630,[1]Sheet3!S537:S1136) -> 0.03 | O32: =_xlfn.XLOOKUP(A32,A31:A630,[1]Sheet3!T537:T1136) -> 8709.27 | P32: =_xlfn.XLOOKUP(A32,A31:A630,[1]Sheet3!U537:U1136) -> 5472.38 | Q32: =_xlfn.XLOOKUP(A32,A31:A630,[1]Sheet3!V537:V1136) -> 0.62833969 | R32: =_xlfn.XLOOKUP(A32,A31:A630,[1]Sheet3!W537:W1136) -> 60.42 | S32: =_xlfn.XLOOKUP(A32,A31:A630,[1]Sheet3!X537:X1136) -> Debit Card | T32: =_xlfn.XLOOKUP(A32,A31:A630,[1]Sheet3!Z537:Z1136) -> 5 | U32: =_xlfn.XLOOKUP(A32,A31:A630,[1]Sheet3!AA537:AA1136) -> FALSE | V32: =_xlfn.XLOOKUP(A32,A31:A630,[1]Sheet3!AC537:AC1136) -> Delivered | W32: =_xlfn.XLOOKUP(A32,A31:A630,[1]Sheet3!AE537:AE1136) -> 1
A33: ORD-00219 | B33: =_xlfn.XLOOKUP(A33,A32:A631,[1]Sheet3!C496:C1095) -> 43926 | C33: =_xlfn.XLOOKUP(A33,A32:A631,[1]Sheet3!D496:D1095) -> CUST81881 | D33: =_xlfn.XLOOKUP(A33,A32:A631,[1]Sheet3!E496:E1095) -> Sanjay Mishra | E33: =_xlfn.XLOOKUP(A33,A32:A631,[1]Sheet3!G496:G1095) -> 34.294221 | F33: =_xlfn.XLOOKUP('Retail Sales'!A497,'Retail Sales'!A496:A1095,[1]Sheet3!H496:H1095) -> Young Adult | G33: =_xlfn.XLOOKUP(A33,A32:A631,[1]Sheet3!J496:J1095) -> Male | H33: =_xlfn.XLOOKUP(A33,A32:A631,[1]Sheet3!K496:K1095) -> Central | I33: =_xlfn.XLOOKUP(A33,A32:A631,[1]Sheet3!L496:L1095) -> Indore | J33: =_xlfn.XLOOKUP(A33,A32:A631,[1]Sheet3!M496:M1095) -> Beauty | K33: =_xlfn.XLOOKUP('Retail Sales'!A497,'Retail Sales'!A496:A1095,[1]Sheet3!N496:N1095) -> Face Cream | L33: =_xlfn.XLOOKUP(A33,A32:A631,[1]Sheet3!P496:P1095) -> 9 | M33: =_xlfn.XLOOKUP(A33,A32:A631,[1]Sheet3!Q496:Q1095) -> 1356.81 | N33: =_xlfn.XLOOKUP(A33,A32:A631,[1]Sheet3!S496:S1095) -> 0.01 | O33: =_xlfn.XLOOKUP(A33,A32:A631,[1]Sheet3!T496:T1095) -> 13938.43 | P33: =_xlfn.XLOOKUP(A33,A32:A631,[1]Sheet3!U496:U1095) -> 5273.14 | Q33: =_xlfn.XLOOKUP(A33,A32:A631,[1]Sheet3!V496:V1095) -> 0.37831664 | R33: =_xlfn.XLOOKUP(A33,A32:A631,[1]Sheet3!W496:W1095) -> 76.63 | S33: =_xlfn.XLOOKUP(A33,A32:A631,[1]Sheet3!X496:X1095) -> Credit Card | T33: =_xlfn.XLOOKUP(A33,A32:A631,[1]Sheet3!Z496:Z1095) -> 3 | U33: =_xlfn.XLOOKUP(A33,A32:A631,[1]Sheet3!AA496:AA1095) -> FALSE | V33: =_xlfn.XLOOKUP(A33,A32:A631,[1]Sheet3!AC496:AC1095) -> Delivered | W33: =_xlfn.XLOOKUP(A33,A32:A631,[1]Sheet3!AE496:AE1095) -> 4
A34: ORD-00225 | B34: =_xlfn.XLOOKUP(A34,A33:A632,[1]Sheet3!C61:C660) -> 43929 | C34: =_xlfn.XLOOKUP(A34,A33:A632,[1]Sheet3!D61:D660) -> CUST97307 | D34: =_xlfn.XLOOKUP(A34,A33:A632,[1]Sheet3!E61:E660) -> Ritu Gupta | E34: =_xlfn.XLOOKUP(A34,A33:A632,[1]Sheet3!G61:G660) -> 37 | F34: =_xlfn.XLOOKUP('Retail Sales'!A62,'Retail Sales'!A61:A660,[1]Sheet3!H61:H660) -> Adult | G34: =_xlfn.XLOOKUP(A34,A33:A632,[1]Sheet3!J61:J660) -> Male | H34: =_xlfn.XLOOKUP(A34,A33:A632,[1]Sheet3!K61:K660) -> Central | I34: =_xlfn.XLOOKUP(A34,A33:A632,[1]Sheet3!L61:L660) -> Nagpur | J34: =_xlfn.XLOOKUP(A34,A33:A632,[1]Sheet3!M61:M660) -> Sports | K34: =_xlfn.XLOOKUP('Retail Sales'!A62,'Retail Sales'!A61:A660,[1]Sheet3!N61:N660) -> Tennis Racket | L34: =_xlfn.XLOOKUP(A34,A33:A632,[1]Sheet3!P61:P660) -> 1 | M34: =_xlfn.XLOOKUP(A34,A33:A632,[1]Sheet3!Q61:Q660) -> 5935.12 | N34: =_xlfn.XLOOKUP(A34,A33:A632,[1]Sheet3!S61:S660) -> 0.08 | O34: =_xlfn.XLOOKUP(A34,A33:A632,[1]Sheet3!T61:T660) -> 6293.66 | P34: =_xlfn.XLOOKUP(A34,A33:A632,[1]Sheet3!U61:U660) -> 1165.63 | Q34: =_xlfn.XLOOKUP(A34,A33:A632,[1]Sheet3!V61:V660) -> 0.18520702 | R34: =_xlfn.XLOOKUP(A34,A33:A632,[1]Sheet3!W61:W660) -> 47.97 | S34: =_xlfn.XLOOKUP(A34,A33:A632,[1]Sheet3!X61:X660) -> Credit Card | T34: =_xlfn.XLOOKUP(A34,A33:A632,[1]Sheet3!Z61:Z660) -> 5 | U34: =_xlfn.XLOOKUP(A34,A33:A632,[1]Sheet3!AA61:AA660) -> FALSE | V34: =_xlfn.XLOOKUP(A34,A33:A632,[1]Sheet3!AC61:AC660) -> Delivered | W34: =_xlfn.XLOOKUP(A34,A33:A632,[1]Sheet3!AE61:AE660) -> 7
A35: ORD-00232 | B35: =_xlfn.XLOOKUP(A35,A34:A633,[1]Sheet3!C437:C1036) -> 43932 | C35: =_xlfn.XLOOKUP(A35,A34:A633,[1]Sheet3!D437:D1036) -> CUST30800 | D35: =_xlfn.XLOOKUP(A35,A34:A633,[1]Sheet3!E437:E1036) -> Rohan Chatterjee | E35: =_xlfn.XLOOKUP(A35,A34:A633,[1]Sheet3!G437:G1036) -> 36 | F35: =_xlfn.XLOOKUP('Retail Sales'!A438,'Retail Sales'!A437:A1036,[1]Sheet3!H437:H1036) -> Adult | G35: =_xlfn.XLOOKUP(A35,A34:A633,[1]Sheet3!J437:J1036) -> Other | H35: =_xlfn.XLOOKUP(A35,A34:A633,[1]Sheet3!K437:K1036) -> Central | I35: =_xlfn.XLOOKUP(A35,A34:A633,[1]Sheet3!L437:L1036) -> Nagpur | J35: =_xlfn.XLOOKUP(A35,A34:A633,[1]Sheet3!M437:M1036) -> Beauty | K35: =_xlfn.XLOOKUP('Retail Sales'!A438,'Retail Sales'!A437:A1036,[1]Sheet3!N437:N1036) -> Perfume | L35: =_xlfn.XLOOKUP(A35,A34:A633,[1]Sheet3!P437:P1036) -> 4 | M35: =_xlfn.XLOOKUP(A35,A34:A633,[1]Sheet3!Q437:Q1036) -> 171.85 | N35: =_xlfn.XLOOKUP(A35,A34:A633,[1]Sheet3!S437:S1036) -> 0.03 | O35: =_xlfn.XLOOKUP(A35,A34:A633,[1]Sheet3!T437:T1036) -> 902.31 | P35: =_xlfn.XLOOKUP(A35,A34:A633,[1]Sheet3!U437:U1036) -> 591.14 | Q35: =_xlfn.XLOOKUP(A35,A34:A633,[1]Sheet3!V437:V1036) -> 0.65514069 | R35: =_xlfn.XLOOKUP(A35,A34:A633,[1]Sheet3!W437:W1036) -> 34.27 | S35: =_xlfn.XLOOKUP(A35,A34:A633,[1]Sheet3!X437:X1036) -> Debit Card | T35: =_xlfn.XLOOKUP(A35,A34:A633,[1]Sheet3!Z437:Z1036) -> 3 | U35: =_xlfn.XLOOKUP(A35,A34:A633,[1]Sheet3!AA437:AA1036) -> FALSE | V35: =_xlfn.XLOOKUP(A35,A34:A633,[1]Sheet3!AC437:AC1036) -> Shipped | W35: =_xlfn.XLOOKUP(A35,A34:A633,[1]Sheet3!AE437:AE1036) -> 8
A36: ORD-00251 | B36: =_xlfn.XLOOKUP(A36,A35:A634,[1]Sheet3!C388:C987) -> 43941 | C36: =_xlfn.XLOOKUP(A36,A35:A634,[1]Sheet3!D388:D987) -> CUST66007 | D36: =_xlfn.XLOOKUP(A36,A35:A634,[1]Sheet3!E388:E987) -> Sunita Bose | E36: =_xlfn.XLOOKUP(A36,A35:A634,[1]Sheet3!G388:G987) -> 26 | F36: =_xlfn.XLOOKUP('Retail Sales'!A389,'Retail Sales'!A388:A987,[1]Sheet3!H388:H987) -> Young Adult | G36: =_xlfn.XLOOKUP(A36,A35:A634,[1]Sheet3!J388:J987) -> Male | H36: =_xlfn.XLOOKUP(A36,A35:A634,[1]Sheet3!K388:K987) -> North | I36: =_xlfn.XLOOKUP(A36,A35:A634,[1]Sheet3!L388:L987) -> Ludhiana | J36: =_xlfn.XLOOKUP(A36,A35:A634,[1]Sheet3!M388:M987) -> Furniture | K36: =_xlfn.XLOOKUP('Retail Sales'!A389,'Retail Sales'!A388:A987,[1]Sheet3!N388:N987) -> Sofa | L36: =_xlfn.XLOOKUP(A36,A35:A634,[1]Sheet3!P388:P987) -> 1 | M36: =_xlfn.XLOOKUP(A36,A35:A634,[1]Sheet3!Q388:Q987) -> 6470.7 | N36: =_xlfn.XLOOKUP(A36,A35:A634,[1]Sheet3!S388:S987) -> 0.34 | O36: =_xlfn.XLOOKUP(A36,A35:A634,[1]Sheet3!T388:T987) -> 4394.74 | P36: =_xlfn.XLOOKUP(A36,A35:A634,[1]Sheet3!U388:U987) -> 1235.03 | Q36: =_xlfn.XLOOKUP(A36,A35:A634,[1]Sheet3!V388:V987) -> 0.28102459 | R36: =_xlfn.XLOOKUP(A36,A35:A634,[1]Sheet3!W388:W987) -> 66.87 | S36: =_xlfn.XLOOKUP(A36,A35:A634,[1]Sheet3!X388:X987) -> Net Banking | T36: =_xlfn.XLOOKUP(A36,A35:A634,[1]Sheet3!Z388:Z987) -> 4 | U36: =_xlfn.XLOOKUP(A36,A35:A634,[1]Sheet3!AA388:AA987) -> FALSE | V36: =_xlfn.XLOOKUP(A36,A35:A634,[1]Sheet3!AC388:AC987) -> Delivered | W36: =_xlfn.XLOOKUP(A36,A35:A634,[1]Sheet3!AE388:AE987) -> 7
A37: ORD-00262 | B37: =_xlfn.XLOOKUP(A37,A36:A635,[1]Sheet3!C243:C842) -> 43946 | C37: =_xlfn.XLOOKUP(A37,A36:A635,[1]Sheet3!D243:D842) -> CUST33827 | D37: =_xlfn.XLOOKUP(A37,A36:A635,[1]Sheet3!E243:E842) -> Rahul Bose | E37: =_xlfn.XLOOKUP(A37,A36:A635,[1]Sheet3!G243:G842) -> 24 | F37: =_xlfn.XLOOKUP('Retail Sales'!A244,'Retail Sales'!A243:A842,[1]Sheet3!H243:H842) -> Young Adult | G37: =_xlfn.XLOOKUP(A37,A36:A635,[1]Sheet3!J243:J842) -> Male | H37: =_xlfn.XLOOKUP(A37,A36:A635,[1]Sheet3!K243:K842) -> West | I37: =_xlfn.XLOOKUP(A37,A36:A635,[1]Sheet3!L243:L842) -> Surat | J37: =_xlfn.XLOOKUP(A37,A36:A635,[1]Sheet3!M243:M842) -> Furniture | K37: =_xlfn.XLOOKUP('Retail Sales'!A244,'Retail Sales'!A243:A842,[1]Sheet3!N243:N842) -> Wardrobe | L37: =_xlfn.XLOOKUP(A37,A36:A635,[1]Sheet3!P243:P842) -> 2 | M37: =_xlfn.XLOOKUP(A37,A36:A635,[1]Sheet3!Q243:Q842) -> 3582.55 | N37: =_xlfn.XLOOKUP(A37,A36:A635,[1]Sheet3!S243:S842) -> 0.08 | O37: =_xlfn.XLOOKUP(A37,A36:A635,[1]Sheet3!T243:T842) -> 8506.99 | P37: =_xlfn.XLOOKUP(A37,A36:A635,[1]Sheet3!U243:U842) -> 2610.08 | Q37: =_xlfn.XLOOKUP(A37,A36:A635,[1]Sheet3!V243:V842) -> 0.30681592 | R37: =_xlfn.XLOOKUP(A37,A36:A635,[1]Sheet3!W243:W842) -> 54.88 | S37: =_xlfn.XLOOKUP(A37,A36:A635,[1]Sheet3!X243:X842) -> Debit Card | T37: =_xlfn.XLOOKUP(A37,A36:A635,[1]Sheet3!Z243:Z842) -> 3 | U37: =_xlfn.XLOOKUP(A37,A36:A635,[1]Sheet3!AA243:AA842) -> FALSE | V37: =_xlfn.XLOOKUP(A37,A36:A635,[1]Sheet3!AC243:AC842) -> Delivered | W37: =_xlfn.XLOOKUP(A37,A36:A635,[1]Sheet3!AE243:AE842) -> 7
A38: ORD-00267 | B38: =_xlfn.XLOOKUP(A38,A37:A636,[1]Sheet3!C366:C965) -> 43948 | C38: =_xlfn.XLOOKUP(A38,A37:A636,[1]Sheet3!D366:D965) -> CUST76356 | D38: =_xlfn.XLOOKUP(A38,A37:A636,[1]Sheet3!E366:E965) -> Aditya Pillai | E38: =_xlfn.XLOOKUP(A38,A37:A636,[1]Sheet3!G366:G965) -> 21 | F38: =_xlfn.XLOOKUP('Retail Sales'!A367,'Retail Sales'!A366:A965,[1]Sheet3!H366:H965) -> Young Adult | G38: =_xlfn.XLOOKUP(A38,A37:A636,[1]Sheet3!J366:J965) -> Female | H38: =_xlfn.XLOOKUP(A38,A37:A636,[1]Sheet3!K366:K965) -> East | I38: =_xlfn.XLOOKUP(A38,A37:A636,[1]Sheet3!L366:L965) -> Kolkata | J38: =_xlfn.XLOOKUP(A38,A37:A636,[1]Sheet3!M366:M965) -> Sports | K38: =_xlfn.XLOOKUP('Retail Sales'!A367,'Retail Sales'!A366:A965,[1]Sheet3!N366:N965) -> Football | L38: =_xlfn.XLOOKUP(A38,A37:A636,[1]Sheet3!P366:P965) -> 6 | M38: =_xlfn.XLOOKUP(A38,A37:A636,[1]Sheet3!Q366:Q965) -> 7876.81 | N38: =_xlfn.XLOOKUP(A38,A37:A636,[1]Sheet3!S366:S965) -> 0.02 | O38: =_xlfn.XLOOKUP(A38,A37:A636,[1]Sheet3!T366:T965) -> 58868.95 | P38: =_xlfn.XLOOKUP(A38,A37:A636,[1]Sheet3!U366:U965) -> 12406.43 | Q38: =_xlfn.XLOOKUP(A38,A37:A636,[1]Sheet3!V366:V965) -> 0.21074658 | R38: =_xlfn.XLOOKUP(A38,A37:A636,[1]Sheet3!W366:W965) -> 62.09 | S38: =_xlfn.XLOOKUP(A38,A37:A636,[1]Sheet3!X366:X965) -> Debit Card | T38: =_xlfn.XLOOKUP(A38,A37:A636,[1]Sheet3!Z366:Z965) -> 4 | U38: =_xlfn.XLOOKUP(A38,A37:A636,[1]Sheet3!AA366:AA965) -> FALSE | V38: =_xlfn.XLOOKUP(A38,A37:A636,[1]Sheet3!AC366:AC965) -> Shipped | W38: =_xlfn.XLOOKUP(A38,A37:A636,[1]Sheet3!AE366:AE965) -> 3
A39: ORD-00268 | B39: =_xlfn.XLOOKUP(A39,A38:A637,[1]Sheet3!C128:C727) -> 43948 | C39: =_xlfn.XLOOKUP(A39,A38:A637,[1]Sheet3!D128:D727) -> CUST64785 | D39: =_xlfn.XLOOKUP(A39,A38:A637,[1]Sheet3!E128:E727) -> Sunita Reddy | E39: =_xlfn.XLOOKUP(A39,A38:A637,[1]Sheet3!G128:G727) -> 32 | F39: =_xlfn.XLOOKUP('Retail Sales'!A129,'Retail Sales'!A128:A727,[1]Sheet3!H128:H727) -> Young Adult | G39: =_xlfn.XLOOKUP(A39,A38:A637,[1]Sheet3!J128:J727) -> Female | H39: =_xlfn.XLOOKUP(A39,A38:A637,[1]Sheet3!K128:K727) -> West | I39: =_xlfn.XLOOKUP(A39,A38:A637,[1]Sheet3!L128:L727) -> Mumbai | J39: =_xlfn.XLOOKUP(A39,A38:A637,[1]Sheet3!M128:M727) -> Books | K39: =_xlfn.XLOOKUP('Retail Sales'!A129,'Retail Sales'!A128:A727,[1]Sheet3!N128:N727) -> Cook Book | L39: =_xlfn.XLOOKUP(A39,A38:A637,[1]Sheet3!P128:P727) -> 7 | M39: =_xlfn.XLOOKUP(A39,A38:A637,[1]Sheet3!Q128:Q727) -> 257.18 | N39: =_xlfn.XLOOKUP(A39,A38:A637,[1]Sheet3!S128:S727) -> 0.29 | O39: =_xlfn.XLOOKUP(A39,A38:A637,[1]Sheet3!T128:T727) -> 1452.88 | P39: =_xlfn.XLOOKUP(A39,A38:A637,[1]Sheet3!U128:U727) -> 604.81 | Q39: =_xlfn.XLOOKUP(A39,A38:A637,[1]Sheet3!V128:V727) -> 0.41628352 | R39: =_xlfn.XLOOKUP(A39,A38:A637,[1]Sheet3!W128:W727) -> 60.36 | S39: =_xlfn.XLOOKUP(A39,A38:A637,[1]Sheet3!X128:X727) -> Credit Card | T39: =_xlfn.XLOOKUP(A39,A38:A637,[1]Sheet3!Z128:Z727) -> 1 | U39: =_xlfn.XLOOKUP(A39,A38:A637,[1]Sheet3!AA128:AA727) -> FALSE | V39: =_xlfn.XLOOKUP(A39,A38:A637,[1]Sheet3!AC128:AC727) -> Cancelled | W39: =_xlfn.XLOOKUP(A39,A38:A637,[1]Sheet3!AE128:AE727) -> 5
A40: ORD-00270 | B40: =_xlfn.XLOOKUP(A40,A39:A638,[1]Sheet3!C423:C1022) -> 43949 | C40: =_xlfn.XLOOKUP(A40,A39:A638,[1]Sheet3!D423:D1022) -> CUST73911 | D40: =_xlfn.XLOOKUP(A40,A39:A638,[1]Sheet3!E423:E1022) -> Ritu Patel | E40: =_xlfn.XLOOKUP(A40,A39:A638,[1]Sheet3!G423:G1022) -> 34.294221 | F40: =_xlfn.XLOOKUP('Retail Sales'!A424,'Retail Sales'!A423:A1022,[1]Sheet3!H423:H1022) -> Young Adult | G40: =_xlfn.XLOOKUP(A40,A39:A638,[1]Sheet3!J423:J1022) -> Other | H40: =_xlfn.XLOOKUP(A40,A39:A638,[1]Sheet3!K423:K1022) -> East | I40: =_xlfn.XLOOKUP(A40,A39:A638,[1]Sheet3!L423:L1022) -> Kolkata | J40: =_xlfn.XLOOKUP(A40,A39:A638,[1]Sheet3!M423:M1022) -> Clothing | K40: =_xlfn.XLOOKUP('Retail Sales'!A424,'Retail Sales'!A423:A1022,[1]Sheet3!N423:N1022) -> Jeans | L40: =_xlfn.XLOOKUP(A40,A39:A638,[1]Sheet3!P423:P1022) -> 6 | M40: =_xlfn.XLOOKUP(A40,A39:A638,[1]Sheet3!Q423:Q1022) -> 2934.92 | N40: =_xlfn.XLOOKUP(A40,A39:A638,[1]Sheet3!S423:S1022) -> 0.1 | O40: =_xlfn.XLOOKUP(A40,A39:A638,[1]Sheet3!T423:T1022) -> 18790.52 | P40: =_xlfn.XLOOKUP(A40,A39:A638,[1]Sheet3!U423:U1022) -> 7715.18 | Q40: =_xlfn.XLOOKUP(A40,A39:A638,[1]Sheet3!V423:V1022) -> 0.41058896 | R40: =_xlfn.XLOOKUP(A40,A39:A638,[1]Sheet3!W423:W1022) -> 74.02 | S40: =_xlfn.XLOOKUP(A40,A39:A638,[1]Sheet3!X423:X1022) -> Debit Card | T40: =_xlfn.XLOOKUP(A40,A39:A638,[1]Sheet3!Z423:Z1022) -> 5 | U40: =_xlfn.XLOOKUP(A40,A39:A638,[1]Sheet3!AA423:AA1022) -> FALSE | V40: =_xlfn.XLOOKUP(A40,A39:A638,[1]Sheet3!AC423:AC1022) -> Cancelled | W40: =_xlfn.XLOOKUP(A40,A39:A638,[1]Sheet3!AE423:AE1022) -> 8
...
